Workbook

Sheet Overview
A1: Purpose | B1: Provides a clean historical input book for Stage 1, PED, light RUC and heavy RUC model inputs. The workbook starts with source values and uses simple Excel formulas for real and log transformations.
A2: Scope | B2: Historical data only. The last row is 2026Q1 because CPI and fuel prices are available for that quarter; there are no forecasts or later-year rows.
A3: Design principle | B3: Source values are entered in Stage 1 Inputs; derived fields use formulas. Missing or unavailable numeric values are stored as zero so the model sheets stay consistent.
A4: CPI anchor | B4: 2026Q1 CPI index = 1339 | C4: Deflators!B2:B3 | D4: Used for petrol, diesel and RUC price rebasing.
A5: GDP anchor | B5: 2025Q4 GDP deflator = 1561 | C5: Deflators!B4:B5 | D5: Used for GDP rebasing because the GDP deflator is not yet available for 2026Q1.
A6: PED model inputs | B6: Includes petrol price, real GDP per capita, unemployment, VKT per capita, total VKT, trend and dummies. | C6: PED Inputs | D6: Linked to Stage 1 Inputs.
A7: Light RUC model inputs | B7: Includes real GDP, diesel price, light RUC price, lagged light RUC price and dummies. | C7: Light RUC Inputs | D7: Linked to Stage 1 Inputs.
A8: Heavy RUC model inputs | B8: Includes real GDP, heavy RUC price, lead heavy RUC price and dummies. Diesel is not used by the heavy RUC model sheet. | C8: Heavy RUC Inputs | D8: Linked to Stage 1 Inputs.

Sheet Deflators
A1: Deflator anchor points
A2: CPI anchor quarter | B2: 2026Q1
A3: CPI anchor index | B3: 1339
A4: GDP anchor quarter | B4: 2025Q4
A5: GDP anchor deflator | B5: 1561
A6: Build note | B6: CPI and fuel series are carried through 2026Q1. GDP, population and labour inputs stop at their latest official quarter. No forecasts are included.
A8: Quarter | B8: Period | C8: CPI index | D8: CPI rebasing factor | E8: GDP deflator (seasonally adjusted) | F8: GDP rebasing factor | G8: Data status | H8: Notes
A9: 2002Q1 | B9: Mar 2002 | C9: 727 | D9: =$B$3/C9 -> 1.8418157 | E9: 835 | F9: =IFERROR($B$5/E9,0) -> 1.8694611 | G9: Official CPI and GDP deflator | H9: No special note
A10: 2002Q2 | B10: Jun 2002 | C10: 734 | D10: =$B$3/C10 -> 1.8242507 | E10: 825 | F10: =IFERROR($B$5/E10,0) -> 1.8921212 | G10: Official CPI and GDP deflator | H10: No special note
A11: 2002Q3 | B11: Sep 2002 | C11: 738 | D11: =$B$3/C11 -> 1.8143631 | E11: 832 | F11: =IFERROR($B$5/E11,0) -> 1.8762019 | G11: Official CPI and GDP deflator | H11: No special note
A12: 2002Q4 | B12: Dec 2002 | C12: 742 | D12: =$B$3/C12 -> 1.8045822 | E12: 820 | F12: =IFERROR($B$5/E12,0) -> 1.9036585 | G12: Official CPI and GDP deflator | H12: No special note
A13: 2003Q1 | B13: Mar 2003 | C13: 745 | D13: =$B$3/C13 -> 1.7973154 | E13: 828 | F13: =IFERROR($B$5/E13,0) -> 1.8852657 | G13: Official CPI and GDP deflator | H13: No special note
A14: 2003Q2 | B14: Jun 2003 | C14: 745 | D14: =$B$3/C14 -> 1.7973154 | E14: 836 | F14: =IFERROR($B$5/E14,0) -> 1.8672249 | G14: Official CPI and GDP deflator | H14: No special note
A15: 2003Q3 | B15: Sep 2003 | C15: 748 | D15: =$B$3/C15 -> 1.790107 | E15: 841 | F15: =IFERROR($B$5/E15,0) -> 1.8561237 | G15: Official CPI and GDP deflator | H15: No special note
A16: 2003Q4 | B16: Dec 2003 | C16: 754 | D16: =$B$3/C16 -> 1.7758621 | E16: 847 | F16: =IFERROR($B$5/E16,0) -> 1.8429752 | G16: Official CPI and GDP deflator | H16: No special note
A17: 2004Q1 | B17: Mar 2004 | C17: 757 | D17: =$B$3/C17 -> 1.7688243 | E17: 850 | F17: =IFERROR($B$5/E17,0) -> 1.8364706 | G17: Official CPI and GDP deflator | H17: No special note
A18: 2004Q2 | B18: Jun 2004 | C18: 763 | D18: =$B$3/C18 -> 1.7549148 | E18: 862 | F18: =IFERROR($B$5/E18,0) -> 1.8109049 | G18: Official CPI and GDP deflator | H18: No special note
A19: 2004Q3 | B19: Sep 2004 | C19: 767 | D19: =$B$3/C19 -> 1.7457627 | E19: 875 | F19: =IFERROR($B$5/E19,0) -> 1.784 | G19: Official CPI and GDP deflator | H19: No special note
A20: 2004Q4 | B20: Dec 2004 | C20: 774 | D20: =$B$3/C20 -> 1.7299742 | E20: 879 | F20: =IFERROR($B$5/E20,0) -> 1.7758817 | G20: Official CPI and GDP deflator | H20: No special note
... A105: 2026Q1 | B105: Mar 2026 | C105: 1339 | D105: =$B$3/C105 -> 1 | E105: 0 | F105: =IFERROR($B$5/E105,0) -> 0 | G105: Official CPI only | H105: CPI anchor quarter; GDP deflator not yet released.

Sheet Stage 1 Inputs
A1: Quarter | B1: Period | C1: CPI index | D1: CPI rebasing factor | E1: GDP deflator (seasonally adjusted) | F1: GDP rebasing factor | G1: Nominal GDP (SA, NZD) | H1: Population | I1: Nominal GDP per capita (NZD) | J1: Real GDP (SA, NZD) | K1: Real GDP per capita (NZD) | L1: Log real GDP | M1: Log real GDP per capita | N1: Petrol price (nominal, cents/litre) | O1: Petrol price (real, cents/litre) | P1: Log real petrol price | Q1: Diesel price (nominal, cents/litre) | R1: Diesel price (real, cents/litre) | S1: Log real diesel price | T1: Light petrol VKT per capita (km) | U1: Light petrol VKT total (km) | V1: Log VKT per capita | W1: Log total VKT | X1: Unemployment (%) | Y1: Unemployment rate | Z1: Log unemployment rate | AA1: Light RUC revenue (NZD) | AB1: Light RUC net km | AC1: Light RUC price (nominal, NZD/1,000 km) | AD1: Light RUC price (real, NZD/1,000 km) | AE1: Log real light RUC price | AF1: Lagged light RUC price (real, NZD/1,000 km) | AG1: Log lagged light RUC price | AH1: Heavy RUC revenue (NZD) | AI1: Heavy RUC net km | AJ1: Heavy RUC price (nominal, NZD/1,000 km) | AK1: Heavy RUC price (real, NZD/1,000 km) | AL1: Log real heavy RUC price | AM1: Lead heavy RUC price (real, NZD/1,000 km) | AN1: Log lead heavy RUC price | AO1: Trend index | AP1: Log trend index | AQ1: Post-2011 dummy | AR1: 2020 dummy | AS1: Post-2020 dummy | AT1: Q2 dummy | AU1: Q3 dummy | AV1: Q4 dummy | AW1: Post-2011 × log trend | AX1: Data status | AY1: Notes
A2: 2002Q1 | B2: Mar 2002 | C2: =Deflators!C9 -> 727 | D2: =Deflators!D9 -> 1.8418157 | E2: =Deflators!E9 -> 835 | F2: =Deflators!F9 -> 1.8694611 | G2: 32976000000 | H2: 3935700 | I2: =IFERROR(G2/H2,0) -> 8378.6874 | J2: =G2*F2 -> 6.1647349e+10 | K2: =IFERROR(J2/H2,0) -> 15663.63 | L2: =IFERROR(LN(J2),0) -> 24.844696 | M2: =IFERROR(LN(K2),0) -> 9.6590967 | N2: 97 | O2: =N2*D2 -> 178.65612 | P2: =IFERROR(LN(O2),0) -> 5.1854628 | Q2: 61.452198 | R2: =Q2*D2 -> 113.18362 | S2: =IFERROR(LN(R2),0) -> 4.7290115 | T2: 1864.0903 | U2: =T2*H2 -> 7.3365003e+09 | V2: =IFERROR(LN(T2),0) -> 7.5305285 | W2: =IFERROR(LN(U2),0) -> 22.716128 | X2: 5.3 | Y2: =X2/100 -> 0.053 | Z2: =IFERROR(LN(Y2),0) -> -2.9374634 | AA2: 0 | AB2: 0 | AC2: =IFERROR(AA2/AB2*1000,0) -> 0 | AD2: =AC2*D2 -> 0 | AE2: =IFERROR(LN(AD2),0) -> 0 | AF2: 0 | AG2: =IFERROR(LN(AF2),0) -> 0 | AH2: 0 | AI2: 0 | AJ2: =IFERROR(AH2/AI2*1000,0) -> 0 | AK2: =AJ2*D2 -> 0 | AL2: =IFERROR(LN(AK2),0) -> 0 | AM2: =IFERROR(AK3,0) -> 0 | AN2: =IFERROR(LN(AM2),0) -> 0 | AO2: 1 | AP2: =LN(AO2) -> 0 | AQ2: 0 | AR2: 0 | AS2: 0 | AT2: 0 | AU2: 0 | AV2: 0 | AW2: =AQ2*AP2 -> 0 | AX2: Historical official/source data | AY2: No special note
A3: 2002Q2 | B3: Jun 2002 | C3: =Deflators!C10 -> 734 | D3: =Deflators!D10 -> 1.8242507 | E3: =Deflators!E10 -> 825 | F3: =Deflators!F10 -> 1.8921212 | G3: 32897000000 | H3: 3948500 | I3: =IFERROR(G3/H3,0) -> 8331.5183 | J3: =G3*F3 -> 6.2245112e+10 | K3: =IFERROR(J3/H3,0) -> 15764.243 | L3: =IFERROR(LN(J3),0) -> 24.854346 | M3: =IFERROR(LN(K3),0) -> 9.6654995 | N3: 106.8 | O3: =N3*D3 -> 194.82997 | P3: =IFERROR(LN(O3),0) -> 5.2721272 | Q3: 65.6 | R3: =Q3*D3 -> 119.67084 | S3: =IFERROR(LN(R3),0) -> 4.784745 | T3: 1854.837 | U3: =T3*H3 -> 7.3238237e+09 | V3: =IFERROR(LN(T3),0) -> 7.5255521 | W3: =IFERROR(LN(U3),0) -> 22.714398 | X3: 5.3 | Y3: =X3/100 -> 0.053 | Z3: =IFERROR(LN(Y3),0) -> -2.9374634 | AA3: 0 | AB3: 0 | AC3: =IFERROR(AA3/AB3*1000,0) -> 0 | AD3: =AC3*D3 -> 0 | AE3: =IFERROR(LN(AD3),0) -> 0 | AF3: =IFERROR(AD2,0) -> 0 | AG3: =IFERROR(LN(AF3),0) -> 0 | AH3: 0 | AI3: 0 | AJ3: =IFERROR(AH3/AI3*1000,0) -> 0 | AK3: =AJ3*D3 -> 0 | AL3: =IFERROR(LN(AK3),0) -> 0 | AM3: =IFERROR(AK4,0) -> 0 | AN3: =IFERROR(LN(AM3),0) -> 0 | AO3: 2 | AP3: =LN(AO3) -> 0.69314718 | AQ3: 0 | AR3: 0 | AS3: 0 | AT3: 1 | AU3: 0 | AV3: 0 | AW3: =AQ3*AP3 -> 0 | AX3: Historical official/source data | AY3: No special note
A4: 2002Q3 | B4: Sep 2002 | C4: =Deflators!C11 -> 738 | D4: =Deflators!D11 -> 1.8143631 | E4: =Deflators!E11 -> 832 | F4: =Deflators!F11 -> 1.8762019 | G4: 33866000000 | H4: 3967600 | I4: =IFERROR(G4/H4,0) -> 8535.6387 | J4: =G4*F4 -> 6.3539454e+10 | K4: =IFERROR(J4/H4,0) -> 16014.582 | L4: =IFERROR(LN(J4),0) -> 24.874927 | M4: =IFERROR(LN(K4),0) -> 9.6812549 | N4: 104.2 | O4: =N4*D4 -> 189.05664 | P4: =IFERROR(LN(O4),0) -> 5.2420467 | Q4: 64.5 | R4: =Q4*D4 -> 117.02642 | S4: =IFERROR(LN(R4),0) -> 4.7623997 | T4: 1862.6786 | U4: =T4*H4 -> 7.3903636e+09 | V4: =IFERROR(LN(T4),0) -> 7.5297708 | W4: =IFERROR(LN(U4),0) -> 22.723443 | X4: 5.5 | Y4: =X4/100 -> 0.055 | Z4: =IFERROR(LN(Y4),0) -> -2.9004221 | AA4: 0 | AB4: 0 | AC4: =IFERROR(AA4/AB4*1000,0) -> 0 | AD4: =AC4*D4 -> 0 | AE4: =IFERROR(LN(AD4),0) -> 0 | AF4: =IFERROR(AD3,0) -> 0 | AG4: =IFERROR(LN(AF4),0) -> 0 | AH4: 0 | AI4: 0 | AJ4: =IFERROR(AH4/AI4*1000,0) -> 0 | AK4: =AJ4*D4 -> 0 | AL4: =IFERROR(LN(AK4),0) -> 0 | AM4: =IFERROR(AK5,0) -> 0 | AN4: =IFERROR(LN(AM4),0) -> 0 | AO4: 3 | AP4: =LN(AO4) -> 1.0986123 | AQ4: 0 | AR4: 0 | AS4: 0 | AT4: 0 | AU4: 1 | AV4: 0 | AW4: =AQ4*AP4 -> 0 | AX4: Historical official/source data | AY4: No special note
A5: 2002Q4 | B5: Dec 2002 | C5: =Deflators!C12 -> 742 | D5: =Deflators!D12 -> 1.8045822 | E5: =Deflators!E12 -> 820 | F5: =Deflators!F12 -> 1.9036585 | G5: 33950000000 | H5: 3989500 | I5: =IFERROR(G5/H5,0) -> 8509.8383 | J5: =G5*F5 -> 6.4629207e+10 | K5: =IFERROR(J5/H5,0) -> 16199.826 | L5: =IFERROR(LN(J5),0) -> 24.891932 | M5: =IFERROR(LN(K5),0) -> 9.6927558 | N5: 103.6 | O5: =N5*D5 -> 186.95472 | P5: =IFERROR(LN(O5),0) -> 5.2308664 | Q5: 65.4 | R5: =Q5*D5 -> 118.01968 | S5: =IFERROR(LN(R5),0) -> 4.7708514 | T5: 1899.2888 | U5: =T5*H5 -> 7.5772128e+09 | V5: =IFERROR(LN(T5),0) -> 7.5492348 | W5: =IFERROR(LN(U5),0) -> 22.748411 | X5: 5.1 | Y5: =X5/100 -> 0.051 | Z5: =IFERROR(LN(Y5),0) -> -2.9759296 | AA5: 0 | AB5: 0 | AC5: =IFERROR(AA5/AB5*1000,0) -> 0 | AD5: =AC5*D5 -> 0 | AE5: =IFERROR(LN(AD5),0) -> 0 | AF5: =IFERROR(AD4,0) -> 0 | AG5: =IFERROR(LN(AF5),0) -> 0 | AH5: 0 | AI5: 0 | AJ5: =IFERROR(AH5/AI5*1000,0) -> 0 | AK5: =AJ5*D5 -> 0 | AL5: =IFERROR(LN(AK5),0) -> 0 | AM5: =IFERROR(AK6,0) -> 0 | AN5: =IFERROR(LN(AM5),0) -> 0 | AO5: 4 | AP5: =LN(AO5) -> 1.3862944 | AQ5: 0 | AR5: 0 | AS5: 0 | AT5: 0 | AU5: 0 | AV5: 1 | AW5: =AQ5*AP5 -> 0 | AX5: Historical official/source data | AY5: No special note
A6: 2003Q1 | B6: Mar 2003 | C6: =Deflators!C13 -> 745 | D6: =Deflators!D13 -> 1.7973154 | E6: =Deflators!E13 -> 828 | F6: =Deflators!F13 -> 1.8852657 | G6: 34462000000 | H6: 4013300 | I6: =IFERROR(G6/H6,0) -> 8586.9484 | J6: =G6*F6 -> 6.4970027e+10 | K6: =IFERROR(J6/H6,0) -> 16188.679 | L6: =IFERROR(LN(J6),0) -> 24.897192 | M6: =IFERROR(LN(K6),0) -> 9.6920675 | N6: 110.2 | O6: =N6*D6 -> 198.06416 | P6: =IFERROR(LN(O6),0) -> 5.288591 | Q6: 70.8 | R6: =Q6*D6 -> 127.24993 | S6: =IFERROR(LN(R6),0) -> 4.8461531 | T6: 1869.6779 | U6: =T6*H6 -> 7.5035783e+09 | V6: =IFERROR(LN(T6),0) -> 7.5335214 | W6: =IFERROR(LN(U6),0) -> 22.738646 | X6: 5 | Y6: =X6/100 -> 0.05 | Z6: =IFERROR(LN(Y6),0) -> -2.9957323 | AA6: 0 | AB6: 0 | AC6: =IFERROR(AA6/AB6*1000,0) -> 0 | AD6: =AC6*D6 -> 0 | AE6: =IFERROR(LN(AD6),0) -> 0 | AF6: =IFERROR(AD5,0) -> 0 | AG6: =IFERROR(LN(AF6),0) -> 0 | AH6: 0 | AI6: 0 | AJ6: =IFERROR(AH6/AI6*1000,0) -> 0 | AK6: =AJ6*D6 -> 0 | AL6: =IFERROR(LN(AK6),0) -> 0 | AM6: =IFERROR(AK7,0) -> 0 | AN6: =IFERROR(LN(AM6),0) -> 0 | AO6: 5 | AP6: =LN(AO6) -> 1.6094379 | AQ6: 0 | AR6: 0 | AS6: 0 | AT6: 0 | AU6: 0 | AV6: 0 | AW6: =AQ6*AP6 -> 0 | AX6: Historical official/source data | AY6: No special note
A7: 2003Q2 | B7: Jun 2003 | C7: =Deflators!C14 -> 745 | D7: =Deflators!D14 -> 1.7973154 | E7: =Deflators!E14 -> 836 | F7: =Deflators!F14 -> 1.8672249 | G7: 34938000000 | H7: 4027200 | I7: =IFERROR(G7/H7,0) -> 8675.5066 | J7: =G7*F7 -> 6.5237103e+10 | K7: =IFERROR(J7/H7,0) -> 16199.122 | L7: =IFERROR(LN(J7),0) -> 24.901294 | M7: =IFERROR(LN(K7),0) -> 9.6927123 | N7: 99.3 | O7: =N7*D7 -> 178.47342 | P7: =IFERROR(LN(O7),0) -> 5.1844397 | Q7: 59.3 | R7: =Q7*D7 -> 106.58081 | S7: =IFERROR(LN(R7),0) -> 4.6689034 | T7: 1857.8789 | U7: =T7*H7 -> 7.4820498e+09 | V7: =IFERROR(LN(T7),0) -> 7.5271907 | W7: =IFERROR(LN(U7),0) -> 22.735773 | X7: 4.8 | Y7: =X7/100 -> 0.048 | Z7: =IFERROR(LN(Y7),0) -> -3.0365543 | AA7: 0 | AB7: 0 | AC7: =IFERROR(AA7/AB7*1000,0) -> 0 | AD7: =AC7*D7 -> 0 | AE7: =IFERROR(LN(AD7),0) -> 0 | AF7: =IFERROR(AD6,0) -> 0 | AG7: =IFERROR(LN(AF7),0) -> 0 | AH7: 0 | AI7: 0 | AJ7: =IFERROR(AH7/AI7*1000,0) -> 0 | AK7: =AJ7*D7 -> 0 | AL7: =IFERROR(LN(AK7),0) -> 0 | AM7: =IFERROR(AK8,0) -> 0 | AN7: =IFERROR(LN(AM7),0) -> 0 | AO7: 6 | AP7: =LN(AO7) -> 1.7917595 | AQ7: 0 | AR7: 0 | AS7: 0 | AT7: 1 | AU7: 0 | AV7: 0 | AW7: =AQ7*AP7 -> 0 | AX7: Historical official/source data | AY7: No special note
A8: 2003Q3 | B8: Sep 2003 | C8: =Deflators!C15 -> 748 | D8: =Deflators!D15 -> 1.790107 | E8: =Deflators!E15 -> 841 | F8: =Deflators!F15 -> 1.8561237 | G8: 35703000000 | H8: 4044600 | I8: =IFERROR(G8/H8,0) -> 8827.3253 | J8: =G8*F8 -> 6.6269183e+10 | K8: =IFERROR(J8/H8,0) -> 16384.607 | L8: =IFERROR(LN(J8),0) -> 24.916991 | M8: =IFERROR(LN(K8),0) -> 9.7040976 | N8: 106.4 | O8: =N8*D8 -> 190.46738 | P8: =IFERROR(LN(O8),0) -> 5.2494809 | Q8: 60.2 | R8: =Q8*D8 -> 107.76444 | S8: =IFERROR(LN(R8),0) -> 4.6799477 | T8: 1866.3677 | U8: =T8*H8 -> 7.548711e+09 | V8: =IFERROR(LN(T8),0) -> 7.5317494 | W8: =IFERROR(LN(U8),0) -> 22.744643 | X8: 4.5 | Y8: =X8/100 -> 0.045 | Z8: =IFERROR(LN(Y8),0) -> -3.1010928 | AA8: 0 | AB8: 0 | AC8: =IFERROR(AA8/AB8*1000,0) -> 0 | AD8: =AC8*D8 -> 0 | AE8: =IFERROR(LN(AD8),0) -> 0 | AF8: =IFERROR(AD7,0) -> 0 | AG8: =IFERROR(LN(AF8),0) -> 0 | AH8: 0 | AI8: 0 | AJ8: =IFERROR(AH8/AI8*1000,0) -> 0 | AK8: =AJ8*D8 -> 0 | AL8: =IFERROR(LN(AK8),0) -> 0 | AM8: =IFERROR(AK9,0) -> 0 | AN8: =IFERROR(LN(AM8),0) -> 0 | AO8: 7 | AP8: =LN(AO8) -> 1.9459101 | AQ8: 0 | AR8: 0 | AS8: 0 | AT8: 0 | AU8: 1 | AV8: 0 | AW8: =AQ8*AP8 -> 0 | AX8: Historical official/source data | AY8: No special note
A9: 2003Q4 | B9: Dec 2003 | C9: =Deflators!C16 -> 754 | D9: =Deflators!D16 -> 1.7758621 | E9: =Deflators!E16 -> 847 | F9: =Deflators!F16 -> 1.8429752 | G9: 36381000000 | H9: 4061600 | I9: =IFERROR(G9/H9,0) -> 8957.3075 | J9: =G9*F9 -> 6.7049281e+10 | K9: =IFERROR(J9/H9,0) -> 16508.096 | L9: =IFERROR(LN(J9),0) -> 24.928694 | M9: =IFERROR(LN(K9),0) -> 9.7116062 | N9: 104.2 | O9: =N9*D9 -> 185.04483 | P9: =IFERROR(LN(O9),0) -> 5.2205981 | Q9: 58.2 | R9: =Q9*D9 -> 103.35517 | S9: =IFERROR(LN(R9),0) -> 4.6381713 | T9: 1902.6145 | U9: =T9*H9 -> 7.7276589e+09 | V9: =IFERROR(LN(T9),0) -> 7.5509843 | W9: =IFERROR(LN(U9),0) -> 22.768072 | X9: 4.7 | Y9: =X9/100 -> 0.047 | Z9: =IFERROR(LN(Y9),0) -> -3.0576077 | AA9: 0 | AB9: 0 | AC9: =IFERROR(AA9/AB9*1000,0) -> 0 | AD9: =AC9*D9 -> 0 | AE9: =IFERROR(LN(AD9),0) -> 0 | AF9: =IFERROR(AD8,0) -> 0 | AG9: =IFERROR(LN(AF9),0) -> 0 | AH9: 0 | AI9: 0 | AJ9: =IFERROR(AH9/AI9*1000,0) -> 0 | AK9: =AJ9*D9 -> 0 | AL9: =IFERROR(LN(AK9),0) -> 0 | AM9: =IFERROR(AK10,0) -> 0 | AN9: =IFERROR(LN(AM9),0) -> 0 | AO9: 8 | AP9: =LN(AO9) -> 2.0794415 | AQ9: 0 | AR9: 0 | AS9: 0 | AT9: 0 | AU9: 0 | AV9: 1 | AW9: =AQ9*AP9 -> 0 | AX9: Historical official/source data | AY9: No special note
A10: 2004Q1 | B10: Mar 2004 | C10: =Deflators!C17 -> 757 | D10: =Deflators!D17 -> 1.7688243 | E10: =Deflators!E17 -> 850 | F10: =Deflators!F17 -> 1.8364706 | G10: 37466000000 | H10: 4078700 | I10: =IFERROR(G10/H10,0) -> 9185.77 | J10: =G10*F10 -> 6.8805207e+10 | K10: =IFERROR(J10/H10,0) -> 16869.396 | L10: =IFERROR(LN(J10),0) -> 24.954545 | M10: =IFERROR(LN(K10),0) -> 9.7332564 | N10: 109.8 | O10: =N10*D10 -> 194.21691 | P10: =IFERROR(LN(O10),0) -> 5.2689756 | Q10: 63.7 | R10: =Q10*D10 -> 112.67411 | S10: =IFERROR(LN(R10),0) -> 4.7244997 | T10: 1893.0122 | U10: =T10*H10 -> 7.7210288e+09 | V10: =IFERROR(LN(T10),0) -> 7.5459246 | W10: =IFERROR(LN(U10),0) -> 22.767213 | X10: 4.3 | Y10: =X10/100 -> 0.043 | Z10: =IFERROR(LN(Y10),0) -> -3.1465552 | AA10: 0 | AB10: 0 | AC10: =IFERROR(AA10/AB10*1000,0) -> 0 | AD10: =AC10*D10 -> 0 | AE10: =IFERROR(LN(AD10),0) -> 0 | AF10: =IFERROR(AD9,0) -> 0 | AG10: =IFERROR(LN(AF10),0) -> 0 | AH10: 0 | AI10: 0 | AJ10: =IFERROR(AH10/AI10*1000,0) -> 0 | AK10: =AJ10*D10 -> 0 | AL10: =IFERROR(LN(AK10),0) -> 0 | AM10: =IFERROR(AK11,0) -> 0 | AN10: =IFERROR(LN(AM10),0) -> 0 | AO10: 9 | AP10: =LN(AO10) -> 2.1972246 | AQ10: 0 | AR10: 0 | AS10: 0 | AT10: 0 | AU10: 0 | AV10: 0 | AW10: =AQ10*AP10 -> 0 | AX10: Historical official/source data | AY10: No special note
A11: 2004Q2 | B11: Jun 2004 | C11: =Deflators!C18 -> 763 | D11: =Deflators!D18 -> 1.7549148 | E11: =Deflators!E18 -> 862 | F11: =Deflators!F18 -> 1.8109049 | G11: 38019000000 | H11: 4087500 | I11: =IFERROR(G11/H11,0) -> 9301.2844 | J11: =G11*F11 -> 6.8848792e+10 | K11: =IFERROR(J11/H11,0) -> 16843.741 | L11: =IFERROR(LN(J11),0) -> 24.955179 | M11: =IFERROR(LN(K11),0) -> 9.7317344 | N11: 118.4 | O11: =N11*D11 -> 207.78191 | P11: =IFERROR(LN(O11),0) -> 5.336489 | Q11: 71.6 | R11: =Q11*D11 -> 125.6519 | S11: =IFERROR(LN(R11),0) -> 4.8335154 | T11: 1857.5758 | U11: =T11*H11 -> 7.5928409e+09 | V11: =IFERROR(LN(T11),0) -> 7.5270276 | W11: =IFERROR(LN(U11),0) -> 22.750472 | X11: 4.2 | Y11: =X11/100 -> 0.042 | Z11: =IFERROR(LN(Y11),0) -> -3.1700857 | AA11: 0 | AB11: 0 | AC11: =IFERROR(AA11/AB11*1000,0) -> 0 | AD11: =AC11*D11 -> 0 | AE11: =IFERROR(LN(AD11),0) -> 0 | AF11: =IFERROR(AD10,0) -> 0 | AG11: =IFERROR(LN(AF11),0) -> 0 | AH11: 0 | AI11: 0 | AJ11: =IFERROR(AH11/AI11*1000,0) -> 0 | AK11: =AJ11*D11 -> 0 | AL11: =IFERROR(LN(AK11),0) -> 0 | AM11: =IFERROR(AK12,0) -> 0 | AN11: =IFERROR(LN(AM11),0) -> 0 | AO11: 10 | AP11: =LN(AO11) -> 2.3025851 | AQ11: 0 | AR11: 0 | AS11: 0 | AT11: 1 | AU11: 0 | AV11: 0 | AW11: =AQ11*AP11 -> 0 | AX11: Historical official/source data | AY11: No special note
A12: 2004Q3 | B12: Sep 2004 | C12: =Deflators!C19 -> 767 | D12: =Deflators!D19 -> 1.7457627 | E12: =Deflators!E19 -> 875 | F12: =Deflators!F19 -> 1.784 | G12: 38645000000 | H12: 4100600 | I12: =IFERROR(G12/H12,0) -> 9424.2306 | J12: =G12*F12 -> 68942680000 | K12: =IFERROR(J12/H12,0) -> 16812.827 | L12: =IFERROR(LN(J12),0) -> 24.956541 | M12: =IFERROR(LN(K12),0) -> 9.7298974 | N12: 119.2 | O12: =N12*D12 -> 208.09492 | P12: =IFERROR(LN(O12),0) -> 5.3379943 | Q12: 76.4 | R12: =Q12*D12 -> 133.37627 | S12: =IFERROR(LN(R12),0) -> 4.8931742 | T12: 1860.3517 | U12: =T12*H12 -> 7.628558e+09 | V12: =IFERROR(LN(T12),0) -> 7.5285208 | W12: =IFERROR(LN(U12),0) -> 22.755165 | X12: 3.9 | Y12: =X12/100 -> 0.039 | Z12: =IFERROR(LN(Y12),0) -> -3.2441936 | AA12: 0 | AB12: 0 | AC12: =IFERROR(AA12/AB12*1000,0) -> 0 | AD12: =AC12*D12 -> 0 | AE12: =IFERROR(LN(AD12),0) -> 0 | AF12: =IFERROR(AD11,0) -> 0 | AG12: =IFERROR(LN(AF12),0) -> 0 | AH12: 0 | AI12: 0 | AJ12: =IFERROR(AH12/AI12*1000,0) -> 0 | AK12: =AJ12*D12 -> 0 | AL12: =IFERROR(LN(AK12),0) -> 0 | AM12: =IFERROR(AK13,0) -> 0 | AN12: =IFERROR(LN(AM12),0) -> 0 | AO12: 11 | AP12: =LN(AO12) -> 2.3978953 | AQ12: 0 | AR12: 0 | AS12: 0 | AT12: 0 | AU12: 1 | AV12: 0 | AW12: =AQ12*AP12 -> 0 | AX12: Historical official/source data | AY12: No special note
A13: 2004Q4 | B13: Dec 2004 | C13: =Deflators!C20 -> 774 | D13: =Deflators!D20 -> 1.7299742 | E13: =Deflators!E20 -> 879 | F13: =Deflators!F20 -> 1.7758817 | G13: 38871000000 | H13: 4114300 | I13: =IFERROR(G13/H13,0) -> 9447.7797 | J13: =G13*F13 -> 6.9030297e+10 | K13: =IFERROR(J13/H13,0) -> 16778.139 | L13: =IFERROR(LN(J13),0) -> 24.957811 | M13: =IFERROR(LN(K13),0) -> 9.7278321 | N13: 118.4 | O13: =N13*D13 -> 204.82894 | P13: =IFERROR(LN(O13),0) -> 5.3221752 | Q13: 80.2 | R13: =Q13*D13 -> 138.74393 | S13: =IFERROR(LN(R13),0) -> 4.93263 | T13: 1897.6679 | U13: =T13*H13 -> 7.8075749e+09 | V13: =IFERROR(LN(T13),0) -> 7.548381 | W13: =IFERROR(LN(U13),0) -> 22.77836 | X13: 3.7 | Y13: =X13/100 -> 0.037 | Z13: =IFERROR(LN(Y13),0) -> -3.2968374 | AA13: 0 | AB13: 0 | AC13: =IFERROR(AA13/AB13*1000,0) -> 0 | AD13: =AC13*D13 -> 0 | AE13: =IFERROR(LN(AD13),0) -> 0 | AF13: =IFERROR(AD12,0) -> 0 | AG13: =IFERROR(LN(AF13),0) -> 0 | AH13: 0 | AI13: 0 | AJ13: =IFERROR(AH13/AI13*1000,0) -> 0 | AK13: =AJ13*D13 -> 0 | AL13: =IFERROR(LN(AK13),0) -> 0 | AM13: =IFERROR(AK14,0) -> 0 | AN13: =IFERROR(LN(AM13),0) -> 0 | AO13: 12 | AP13: =LN(AO13) -> 2.4849066 | AQ13: 0 | AR13: 0 | AS13: 0 | AT13: 0 | AU13: 0 | AV13: 1 | AW13: =AQ13*AP13 -> 0 | AX13: Historical official/source data | AY13: No special note
A14: 2005Q1 | B14: Mar 2005 | C14: =Deflators!C21 -> 778 | D14: =Deflators!D21 -> 1.7210797 | E14: =Deflators!E21 -> 880 | F14: =Deflators!F21 -> 1.7738636 | G14: 39022000000 | H14: 4126600 | I14: =IFERROR(G14/H14,0) -> 9456.2109 | J14: =G14*F14 -> 6.9219707e+10 | K14: =IFERROR(J14/H14,0) -> 16774.029 | L14: =IFERROR(LN(J14),0) -> 24.960551 | M14: =IFERROR(LN(K14),0) -> 9.7275871 | N14: 118.3 | O14: =N14*D14 -> 203.60373 | P14: =IFERROR(LN(O14),0) -> 5.3161756 | Q14: 79 | R14: =Q14*D14 -> 135.9653 | S14: =IFERROR(LN(R14),0) -> 4.9123997 | T14: 1872.5973 | U14: =T14*H14 -> 7.7274602e+09 | V14: =IFERROR(LN(T14),0) -> 7.5350817 | W14: =IFERROR(LN(U14),0) -> 22.768046 | X14: 3.9 | Y14: =X14/100 -> 0.039 | Z14: =IFERROR(LN(Y14),0) -> -3.2441936 | AA14: 0 | AB14: 0 | AC14: =IFERROR(AA14/AB14*1000,0) -> 0 | AD14: =AC14*D14 -> 0 | AE14: =IFERROR(LN(AD14),0) -> 0 | AF14: =IFERROR(AD13,0) -> 0 | AG14: =IFERROR(LN(AF14),0) -> 0 | AH14: 0 | AI14: 0 | AJ14: =IFERROR(AH14/AI14*1000,0) -> 0 | AK14: =AJ14*D14 -> 0 | AL14: =IFERROR(LN(AK14),0) -> 0 | AM14: =IFERROR(AK15,0) -> 0 | AN14: =IFERROR(LN(AM14),0) -> 0 | AO14: 13 | AP14: =LN(AO14) -> 2.5649494 | AQ14: 0 | AR14: 0 | AS14: 0 | AT14: 0 | AU14: 0 | AV14: 0 | AW14: =AQ14*AP14 -> 0 | AX14: Historical official/source data | AY14: No special note
... A97: 2025Q4 | B97: Dec 2025 | C97: =Deflators!C104 -> 1327 | D97: =Deflators!D104 -> 1.009043 | E97: =Deflators!E104 -> 1561 | F97: =Deflators!F104 -> 1 | G97: 113094000000 | H97: 5342000 | I97: =IFERROR(G97/H97,0) -> 21170.723 | J97: =G97*F97 -> 113094000000 | K97: =IFERROR(J97/H97,0) -> 21170.723 | L97: =IFERROR(LN(J97),0) -> 25.451485 | M97: =IFERROR(LN(K97),0) -> 9.9603745 | N97: 260.6 | O97: =N97*D97 -> 262.95659 | P97: =IFERROR(LN(O97),0) -> 5.571989 | Q97: 192.8 | R97: =Q97*D97 -> 194.54348 | S97: =IFERROR(LN(R97),0) -> 5.2706557 | T97: 1565.5435 | U97: =T97*H97 -> 8.3631336e+09 | V97: =IFERROR(LN(T97),0) -> 7.3559883 | W97: =IFERROR(LN(U97),0) -> 22.847099 | X97: 5.4 | Y97: =X97/100 -> 0.054 | Z97: =IFERROR(LN(Y97),0) -> -2.9187712 | AA97: 2.5774014e+08 | AB97: 3307965543 | AC97: =IFERROR(AA97/AB97*1000,0) -> 77.915003 | AD97: =AC97*D97 -> 78.619585 | AE97: =IFERROR(LN(AD97),0) -> 4.3646208 | AF97: =IFERROR(AD96,0) -> 79.048654 | AG97: =IFERROR(LN(AF97),0) -> 4.3700635 | AH97: 3.4153388e+08 | AI97: 1064388483 | AJ97: =IFERROR(AH97/AI97*1000,0) -> 320.87333 | AK97: =AJ97*D97 -> 323.77498 | AL97: =IFERROR(LN(AK97),0) -> 5.7800488 | AM97: =IFERROR(AK98,0) -> 0 | AN97: =IFERROR(LN(AM97),0) -> 0 | AO97: 96 | AP97: =LN(AO97) -> 4.5643482 | AQ97: 1 | AR97: 0 | AS97: 1 | AT97: 0 | AU97: 0 | AV97: 1 | AW97: =AQ97*AP97 -> 4.5643482 | AX97: Historical official/source data | AY97: Latest full official quarter for GDP, population, labour and RUC/VKT inputs. Fuel prices refreshed from Stats NZ CPI detailed table.
A98: 2026Q1 | B98: Mar 2026 | C98: =Deflators!C105 -> 1339 | D98: =Deflators!D105 -> 1 | E98: =Deflators!E105 -> 0 | F98: =Deflators!F105 -> 0 | G98: 0 | H98: 0 | I98: =IFERROR(G98/H98,0) -> 0 | J98: =G98*F98 -> 0 | K98: =IFERROR(J98/H98,0) -> 0 | L98: =IFERROR(LN(J98),0) -> 0 | M98: =IFERROR(LN(K98),0) -> 0 | N98: 269.8 | O98: =N98*D98 -> 269.8 | P98: =IFERROR(LN(O98),0) -> 5.5976809 | Q98: 214.6 | R98: =Q98*D98 -> 214.6 | S98: =IFERROR(LN(R98),0) -> 5.3687758 | T98: 0 | U98: =T98*H98 -> 0 | V98: =IFERROR(LN(T98),0) -> 0 | W98: =IFERROR(LN(U98),0) -> 0 | X98: 0 | Y98: =X98/100 -> 0 | Z98: =IFERROR(LN(Y98),0) -> 0 | AA98: 0 | AB98: 0 | AC98: =IFERROR(AA98/AB98*1000,0) -> 0 | AD98: =AC98*D98 -> 0 | AE98: =IFERROR(LN(AD98),0) -> 0 | AF98: =IFERROR(AD97,0) -> 78.619585 | AG98: =IFERROR(LN(AF98),0) -> 4.3646208 | AH98: 0 | AI98: 0 | AJ98: =IFERROR(AH98/AI98*1000,0) -> 0 | AK98: =AJ98*D98 -> 0 | AL98: =IFERROR(LN(AK98),0) -> 0 | AM98: 0 | AN98: =IFERROR(LN(AM98),0) -> 0 | AO98: 97 | AP98: =LN(AO98) -> 4.574711 | AQ98: 1 | AR98: 0 | AS98: 1 | AT98: 0 | AU98: 0 | AV98: 0 | AW98: =AQ98*AP98 -> 4.574711 | AX98: Partial official CPI and fuel update | AY98: CPI and fuel values are official; GDP, population, labour, VKT and RUC volume/revenue are not yet released and remain zero.

Sheet PED Inputs
A1: Quarter | B1: Period | C1: Nominal GDP (SA, NZD) | D1: Population | E1: Nominal GDP per capita (NZD) | F1: GDP deflator (seasonally adjusted) | G1: GDP rebasing factor | H1: Real GDP per capita (NZD) | I1: Log real GDP per capita | J1: Petrol price (nominal, cents/litre) | K1: CPI rebasing factor | L1: Petrol price (real, cents/litre) | M1: Log real petrol price | N1: Light petrol VKT per capita (km) | O1: Light petrol VKT total (km) | P1: Log VKT per capita | Q1: Log total VKT | R1: Unemployment (%) | S1: Unemployment rate | T1: Log unemployment rate | U1: Trend index | V1: Log trend index | W1: Post-2011 dummy | X1: 2020 dummy | Y1: Post-2020 dummy | Z1: Q2 dummy | AA1: Q3 dummy | AB1: Q4 dummy | AC1: Post-2011 × log trend | AD1: Data status | AE1: Notes
A2: ='Stage 1 Inputs'!A2 -> 2002Q1 | B2: ='Stage 1 Inputs'!B2 -> Mar 2002 | C2: ='Stage 1 Inputs'!G2 -> 32976000000 | D2: ='Stage 1 Inputs'!H2 -> 3935700 | E2: ='Stage 1 Inputs'!I2 -> 8378.6874 | F2: ='Stage 1 Inputs'!E2 -> 835 | G2: ='Stage 1 Inputs'!F2 -> 1.8694611 | H2: ='Stage 1 Inputs'!K2 -> 15663.63 | I2: ='Stage 1 Inputs'!M2 -> 9.6590967 | J2: ='Stage 1 Inputs'!N2 -> 97 | K2: ='Stage 1 Inputs'!D2 -> 1.8418157 | L2: ='Stage 1 Inputs'!O2 -> 178.65612 | M2: ='Stage 1 Inputs'!P2 -> 5.1854628 | N2: ='Stage 1 Inputs'!T2 -> 1864.0903 | O2: ='Stage 1 Inputs'!U2 -> 7.3365003e+09 | P2: ='Stage 1 Inputs'!V2 -> 7.5305285 | Q2: ='Stage 1 Inputs'!W2 -> 22.716128 | R2: ='Stage 1 Inputs'!X2 -> 5.3 | S2: ='Stage 1 Inputs'!Y2 -> 0.053 | T2: ='Stage 1 Inputs'!Z2 -> -2.9374634 | U2: ='Stage 1 Inputs'!AO2 -> 1 | V2: ='Stage 1 Inputs'!AP2 -> 0 | W2: ='Stage 1 Inputs'!AQ2 -> 0 | X2: ='Stage 1 Inputs'!AR2 -> 0 | Y2: ='Stage 1 Inputs'!AS2 -> 0 | Z2: ='Stage 1 Inputs'!AT2 -> 0 | AA2: ='Stage 1 Inputs'!AU2 -> 0 | AB2: ='Stage 1 Inputs'!AV2 -> 0 | ... AE2: ='Stage 1 Inputs'!AY2 -> No special note
A3: ='Stage 1 Inputs'!A3 -> 2002Q2 | B3: ='Stage 1 Inputs'!B3 -> Jun 2002 | C3: ='Stage 1 Inputs'!G3 -> 32897000000 | D3: ='Stage 1 Inputs'!H3 -> 3948500 | E3: ='Stage 1 Inputs'!I3 -> 8331.5183 | F3: ='Stage 1 Inputs'!E3 -> 825 | G3: ='Stage 1 Inputs'!F3 -> 1.8921212 | H3: ='Stage 1 Inputs'!K3 -> 15764.243 | I3: ='Stage 1 Inputs'!M3 -> 9.6654995 | J3: ='Stage 1 Inputs'!N3 -> 106.8 | K3: ='Stage 1 Inputs'!D3 -> 1.8242507 | L3: ='Stage 1 Inputs'!O3 -> 194.82997 | M3: ='Stage 1 Inputs'!P3 -> 5.2721272 | N3: ='Stage 1 Inputs'!T3 -> 1854.837 | O3: ='Stage 1 Inputs'!U3 -> 7.3238237e+09 | P3: ='Stage 1 Inputs'!V3 -> 7.5255521 | Q3: ='Stage 1 Inputs'!W3 -> 22.714398 | R3: ='Stage 1 Inputs'!X3 -> 5.3 | S3: ='Stage 1 Inputs'!Y3 -> 0.053 | T3: ='Stage 1 Inputs'!Z3 -> -2.9374634 | U3: ='Stage 1 Inputs'!AO3 -> 2 | V3: ='Stage 1 Inputs'!AP3 -> 0.69314718 | W3: ='Stage 1 Inputs'!AQ3 -> 0 | X3: ='Stage 1 Inputs'!AR3 -> 0 | Y3: ='Stage 1 Inputs'!AS3 -> 0 | Z3: ='Stage 1 Inputs'!AT3 -> 1 | AA3: ='Stage 1 Inputs'!AU3 -> 0 | AB3: ='Stage 1 Inputs'!AV3 -> 0 | ... AE3: ='Stage 1 Inputs'!AY3 -> No special note
A4: ='Stage 1 Inputs'!A4 -> 2002Q3 | B4: ='Stage 1 Inputs'!B4 -> Sep 2002 | C4: ='Stage 1 Inputs'!G4 -> 33866000000 | D4: ='Stage 1 Inputs'!H4 -> 3967600 | E4: ='Stage 1 Inputs'!I4 -> 8535.6387 | F4: ='Stage 1 Inputs'!E4 -> 832 | G4: ='Stage 1 Inputs'!F4 -> 1.8762019 | H4: ='Stage 1 Inputs'!K4 -> 16014.582 | I4: ='Stage 1 Inputs'!M4 -> 9.6812549 | J4: ='Stage 1 Inputs'!N4 -> 104.2 | K4: ='Stage 1 Inputs'!D4 -> 1.8143631 | L4: ='Stage 1 Inputs'!O4 -> 189.05664 | M4: ='Stage 1 Inputs'!P4 -> 5.2420467 | N4: ='Stage 1 Inputs'!T4 -> 1862.6786 | O4: ='Stage 1 Inputs'!U4 -> 7.3903636e+09 | P4: ='Stage 1 Inputs'!V4 -> 7.5297708 | Q4: ='Stage 1 Inputs'!W4 -> 22.723443 | R4: ='Stage 1 Inputs'!X4 -> 5.5 | S4: ='Stage 1 Inputs'!Y4 -> 0.055 | T4: ='Stage 1 Inputs'!Z4 -> -2.9004221 | U4: ='Stage 1 Inputs'!AO4 -> 3 | V4: ='Stage 1 Inputs'!AP4 -> 1.0986123 | W4: ='Stage 1 Inputs'!AQ4 -> 0 | X4: ='Stage 1 Inputs'!AR4 -> 0 | Y4: ='Stage 1 Inputs'!AS4 -> 0 | Z4: ='Stage 1 Inputs'!AT4 -> 0 | AA4: ='Stage 1 Inputs'!AU4 -> 1 | AB4: ='Stage 1 Inputs'!AV4 -> 0 | ... AE4: ='Stage 1 Inputs'!AY4 -> No special note
A5: ='Stage 1 Inputs'!A5 -> 2002Q4 | B5: ='Stage 1 Inputs'!B5 -> Dec 2002 | C5: ='Stage 1 Inputs'!G5 -> 33950000000 | D5: ='Stage 1 Inputs'!H5 -> 3989500 | E5: ='Stage 1 Inputs'!I5 -> 8509.8383 | F5: ='Stage 1 Inputs'!E5 -> 820 | G5: ='Stage 1 Inputs'!F5 -> 1.9036585 | H5: ='Stage 1 Inputs'!K5 -> 16199.826 | I5: ='Stage 1 Inputs'!M5 -> 9.6927558 | J5: ='Stage 1 Inputs'!N5 -> 103.6 | K5: ='Stage 1 Inputs'!D5 -> 1.8045822 | L5: ='Stage 1 Inputs'!O5 -> 186.95472 | M5: ='Stage 1 Inputs'!P5 -> 5.2308664 | N5: ='Stage 1 Inputs'!T5 -> 1899.2888 | O5: ='Stage 1 Inputs'!U5 -> 7.5772128e+09 | P5: ='Stage 1 Inputs'!V5 -> 7.5492348 | Q5: ='Stage 1 Inputs'!W5 -> 22.748411 | R5: ='Stage 1 Inputs'!X5 -> 5.1 | S5: ='Stage 1 Inputs'!Y5 -> 0.051 | T5: ='Stage 1 Inputs'!Z5 -> -2.9759296 | U5: ='Stage 1 Inputs'!AO5 -> 4 | V5: ='Stage 1 Inputs'!AP5 -> 1.3862944 | W5: ='Stage 1 Inputs'!AQ5 -> 0 | X5: ='Stage 1 Inputs'!AR5 -> 0 | Y5: ='Stage 1 Inputs'!AS5 -> 0 | Z5: ='Stage 1 Inputs'!AT5 -> 0 | AA5: ='Stage 1 Inputs'!AU5 -> 0 | AB5: ='Stage 1 Inputs'!AV5 -> 1 | ... AE5: ='Stage 1 Inputs'!AY5 -> No special note
A6: ='Stage 1 Inputs'!A6 -> 2003Q1 | B6: ='Stage 1 Inputs'!B6 -> Mar 2003 | C6: ='Stage 1 Inputs'!G6 -> 34462000000 | D6: ='Stage 1 Inputs'!H6 -> 4013300 | E6: ='Stage 1 Inputs'!I6 -> 8586.9484 | F6: ='Stage 1 Inputs'!E6 -> 828 | G6: ='Stage 1 Inputs'!F6 -> 1.8852657 | H6: ='Stage 1 Inputs'!K6 -> 16188.679 | I6: ='Stage 1 Inputs'!M6 -> 9.6920675 | J6: ='Stage 1 Inputs'!N6 -> 110.2 | K6: ='Stage 1 Inputs'!D6 -> 1.7973154 | L6: ='Stage 1 Inputs'!O6 -> 198.06416 | M6: ='Stage 1 Inputs'!P6 -> 5.288591 | N6: ='Stage 1 Inputs'!T6 -> 1869.6779 | O6: ='Stage 1 Inputs'!U6 -> 7.5035783e+09 | P6: ='Stage 1 Inputs'!V6 -> 7.5335214 | Q6: ='Stage 1 Inputs'!W6 -> 22.738646 | R6: ='Stage 1 Inputs'!X6 -> 5 | S6: ='Stage 1 Inputs'!Y6 -> 0.05 | T6: ='Stage 1 Inputs'!Z6 -> -2.9957323 | U6: ='Stage 1 Inputs'!AO6 -> 5 | V6: ='Stage 1 Inputs'!AP6 -> 1.6094379 | W6: ='Stage 1 Inputs'!AQ6 -> 0 | X6: ='Stage 1 Inputs'!AR6 -> 0 | Y6: ='Stage 1 Inputs'!AS6 -> 0 | Z6: ='Stage 1 Inputs'!AT6 -> 0 | AA6: ='Stage 1 Inputs'!AU6 -> 0 | AB6: ='Stage 1 Inputs'!AV6 -> 0 | ... AE6: ='Stage 1 Inputs'!AY6 -> No special note
A7: ='Stage 1 Inputs'!A7 -> 2003Q2 | B7: ='Stage 1 Inputs'!B7 -> Jun 2003 | C7: ='Stage 1 Inputs'!G7 -> 34938000000 | D7: ='Stage 1 Inputs'!H7 -> 4027200 | E7: ='Stage 1 Inputs'!I7 -> 8675.5066 | F7: ='Stage 1 Inputs'!E7 -> 836 | G7: ='Stage 1 Inputs'!F7 -> 1.8672249 | H7: ='Stage 1 Inputs'!K7 -> 16199.122 | I7: ='Stage 1 Inputs'!M7 -> 9.6927123 | J7: ='Stage 1 Inputs'!N7 -> 99.3 | K7: ='Stage 1 Inputs'!D7 -> 1.7973154 | L7: ='Stage 1 Inputs'!O7 -> 178.47342 | M7: ='Stage 1 Inputs'!P7 -> 5.1844397 | N7: ='Stage 1 Inputs'!T7 -> 1857.8789 | O7: ='Stage 1 Inputs'!U7 -> 7.4820498e+09 | P7: ='Stage 1 Inputs'!V7 -> 7.5271907 | Q7: ='Stage 1 Inputs'!W7 -> 22.735773 | R7: ='Stage 1 Inputs'!X7 -> 4.8 | S7: ='Stage 1 Inputs'!Y7 -> 0.048 | T7: ='Stage 1 Inputs'!Z7 -> -3.0365543 | U7: ='Stage 1 Inputs'!AO7 -> 6 | V7: ='Stage 1 Inputs'!AP7 -> 1.7917595 | W7: ='Stage 1 Inputs'!AQ7 -> 0 | X7: ='Stage 1 Inputs'!AR7 -> 0 | Y7: ='Stage 1 Inputs'!AS7 -> 0 | Z7: ='Stage 1 Inputs'!AT7 -> 1 | AA7: ='Stage 1 Inputs'!AU7 -> 0 | AB7: ='Stage 1 Inputs'!AV7 -> 0 | ... AE7: ='Stage 1 Inputs'!AY7 -> No special note
A8: ='Stage 1 Inputs'!A8 -> 2003Q3 | B8: ='Stage 1 Inputs'!B8 -> Sep 2003 | C8: ='Stage 1 Inputs'!G8 -> 35703000000 | D8: ='Stage 1 Inputs'!H8 -> 4044600 | E8: ='Stage 1 Inputs'!I8 -> 8827.3253 | F8: ='Stage 1 Inputs'!E8 -> 841 | G8: ='Stage 1 Inputs'!F8 -> 1.8561237 | H8: ='Stage 1 Inputs'!K8 -> 16384.607 | I8: ='Stage 1 Inputs'!M8 -> 9.7040976 | J8: ='Stage 1 Inputs'!N8 -> 106.4 | K8: ='Stage 1 Inputs'!D8 -> 1.790107 | L8: ='Stage 1 Inputs'!O8 -> 190.46738 | M8: ='Stage 1 Inputs'!P8 -> 5.2494809 | N8: ='Stage 1 Inputs'!T8 -> 1866.3677 | O8: ='Stage 1 Inputs'!U8 -> 7.548711e+09 | P8: ='Stage 1 Inputs'!V8 -> 7.5317494 | Q8: ='Stage 1 Inputs'!W8 -> 22.744643 | R8: ='Stage 1 Inputs'!X8 -> 4.5 | S8: ='Stage 1 Inputs'!Y8 -> 0.045 | T8: ='Stage 1 Inputs'!Z8 -> -3.1010928 | U8: ='Stage 1 Inputs'!AO8 -> 7 | V8: ='Stage 1 Inputs'!AP8 -> 1.9459101 | W8: ='Stage 1 Inputs'!AQ8 -> 0 | X8: ='Stage 1 Inputs'!AR8 -> 0 | Y8: ='Stage 1 Inputs'!AS8 -> 0 | Z8: ='Stage 1 Inputs'!AT8 -> 0 | AA8: ='Stage 1 Inputs'!AU8 -> 1 | AB8: ='Stage 1 Inputs'!AV8 -> 0 | ... AE8: ='Stage 1 Inputs'!AY8 -> No special note
A9: ='Stage 1 Inputs'!A9 -> 2003Q4 | B9: ='Stage 1 Inputs'!B9 -> Dec 2003 | C9: ='Stage 1 Inputs'!G9 -> 36381000000 | D9: ='Stage 1 Inputs'!H9 -> 4061600 | E9: ='Stage 1 Inputs'!I9 -> 8957.3075 | F9: ='Stage 1 Inputs'!E9 -> 847 | G9: ='Stage 1 Inputs'!F9 -> 1.8429752 | H9: ='Stage 1 Inputs'!K9 -> 16508.096 | I9: ='Stage 1 Inputs'!M9 -> 9.7116062 | J9: ='Stage 1 Inputs'!N9 -> 104.2 | K9: ='Stage 1 Inputs'!D9 -> 1.7758621 | L9: ='Stage 1 Inputs'!O9 -> 185.04483 | M9: ='Stage 1 Inputs'!P9 -> 5.2205981 | N9: ='Stage 1 Inputs'!T9 -> 1902.6145 | O9: ='Stage 1 Inputs'!U9 -> 7.7276589e+09 | P9: ='Stage 1 Inputs'!V9 -> 7.5509843 | Q9: ='Stage 1 Inputs'!W9 -> 22.768072 | R9: ='Stage 1 Inputs'!X9 -> 4.7 | S9: ='Stage 1 Inputs'!Y9 -> 0.047 | T9: ='Stage 1 Inputs'!Z9 -> -3.0576077 | U9: ='Stage 1 Inputs'!AO9 -> 8 | V9: ='Stage 1 Inputs'!AP9 -> 2.0794415 | W9: ='Stage 1 Inputs'!AQ9 -> 0 | X9: ='Stage 1 Inputs'!AR9 -> 0 | Y9: ='Stage 1 Inputs'!AS9 -> 0 | Z9: ='Stage 1 Inputs'!AT9 -> 0 | AA9: ='Stage 1 Inputs'!AU9 -> 0 | AB9: ='Stage 1 Inputs'!AV9 -> 1 | ... AE9: ='Stage 1 Inputs'!AY9 -> No special note
A10: ='Stage 1 Inputs'!A10 -> 2004Q1 | B10: ='Stage 1 Inputs'!B10 -> Mar 2004 | C10: ='Stage 1 Inputs'!G10 -> 37466000000 | D10: ='Stage 1 Inputs'!H10 -> 4078700 | E10: ='Stage 1 Inputs'!I10 -> 9185.77 | F10: ='Stage 1 Inputs'!E10 -> 850 | G10: ='Stage 1 Inputs'!F10 -> 1.8364706 | H10: ='Stage 1 Inputs'!K10 -> 16869.396 | I10: ='Stage 1 Inputs'!M10 -> 9.7332564 | J10: ='Stage 1 Inputs'!N10 -> 109.8 | K10: ='Stage 1 Inputs'!D10 -> 1.7688243 | L10: ='Stage 1 Inputs'!O10 -> 194.21691 | M10: ='Stage 1 Inputs'!P10 -> 5.2689756 | N10: ='Stage 1 Inputs'!T10 -> 1893.0122 | O10: ='Stage 1 Inputs'!U10 -> 7.7210288e+09 | P10: ='Stage 1 Inputs'!V10 -> 7.5459246 | Q10: ='Stage 1 Inputs'!W10 -> 22.767213 | R10: ='Stage 1 Inputs'!X10 -> 4.3 | S10: ='Stage 1 Inputs'!Y10 -> 0.043 | T10: ='Stage 1 Inputs'!Z10 -> -3.1465552 | U10: ='Stage 1 Inputs'!AO10 -> 9 | V10: ='Stage 1 Inputs'!AP10 -> 2.1972246 | W10: ='Stage 1 Inputs'!AQ10 -> 0 | X10: ='Stage 1 Inputs'!AR10 -> 0 | Y10: ='Stage 1 Inputs'!AS10 -> 0 | Z10: ='Stage 1 Inputs'!AT10 -> 0 | AA10: ='Stage 1 Inputs'!AU10 -> 0 | AB10: ='Stage 1 Inputs'!AV10 -> 0 | ... AE10: ='Stage 1 Inputs'!AY10 -> No special note
A11: ='Stage 1 Inputs'!A11 -> 2004Q2 | B11: ='Stage 1 Inputs'!B11 -> Jun 2004 | C11: ='Stage 1 Inputs'!G11 -> 38019000000 | D11: ='Stage 1 Inputs'!H11 -> 4087500 | E11: ='Stage 1 Inputs'!I11 -> 9301.2844 | F11: ='Stage 1 Inputs'!E11 -> 862 | G11: ='Stage 1 Inputs'!F11 -> 1.8109049 | H11: ='Stage 1 Inputs'!K11 -> 16843.741 | I11: ='Stage 1 Inputs'!M11 -> 9.7317344 | J11: ='Stage 1 Inputs'!N11 -> 118.4 | K11: ='Stage 1 Inputs'!D11 -> 1.7549148 | L11: ='Stage 1 Inputs'!O11 -> 207.78191 | M11: ='Stage 1 Inputs'!P11 -> 5.336489 | N11: ='Stage 1 Inputs'!T11 -> 1857.5758 | O11: ='Stage 1 Inputs'!U11 -> 7.5928409e+09 | P11: ='Stage 1 Inputs'!V11 -> 7.5270276 | Q11: ='Stage 1 Inputs'!W11 -> 22.750472 | R11: ='Stage 1 Inputs'!X11 -> 4.2 | S11: ='Stage 1 Inputs'!Y11 -> 0.042 | T11: ='Stage 1 Inputs'!Z11 -> -3.1700857 | U11: ='Stage 1 Inputs'!AO11 -> 10 | V11: ='Stage 1 Inputs'!AP11 -> 2.3025851 | W11: ='Stage 1 Inputs'!AQ11 -> 0 | X11: ='Stage 1 Inputs'!AR11 -> 0 | Y11: ='Stage 1 Inputs'!AS11 -> 0 | Z11: ='Stage 1 Inputs'!AT11 -> 1 | AA11: ='Stage 1 Inputs'!AU11 -> 0 | AB11: ='Stage 1 Inputs'!AV11 -> 0 | ... AE11: ='Stage 1 Inputs'!AY11 -> No special note
A12: ='Stage 1 Inputs'!A12 -> 2004Q3 | B12: ='Stage 1 Inputs'!B12 -> Sep 2004 | C12: ='Stage 1 Inputs'!G12 -> 38645000000 | D12: ='Stage 1 Inputs'!H12 -> 4100600 | E12: ='Stage 1 Inputs'!I12 -> 9424.2306 | F12: ='Stage 1 Inputs'!E12 -> 875 | G12: ='Stage 1 Inputs'!F12 -> 1.784 | H12: ='Stage 1 Inputs'!K12 -> 16812.827 | I12: ='Stage 1 Inputs'!M12 -> 9.7298974 | J12: ='Stage 1 Inputs'!N12 -> 119.2 | K12: ='Stage 1 Inputs'!D12 -> 1.7457627 | L12: ='Stage 1 Inputs'!O12 -> 208.09492 | M12: ='Stage 1 Inputs'!P12 -> 5.3379943 | N12: ='Stage 1 Inputs'!T12 -> 1860.3517 | O12: ='Stage 1 Inputs'!U12 -> 7.628558e+09 | P12: ='Stage 1 Inputs'!V12 -> 7.5285208 | Q12: ='Stage 1 Inputs'!W12 -> 22.755165 | R12: ='Stage 1 Inputs'!X12 -> 3.9 | S12: ='Stage 1 Inputs'!Y12 -> 0.039 | T12: ='Stage 1 Inputs'!Z12 -> -3.2441936 | U12: ='Stage 1 Inputs'!AO12 -> 11 | V12: ='Stage 1 Inputs'!AP12 -> 2.3978953 | W12: ='Stage 1 Inputs'!AQ12 -> 0 | X12: ='Stage 1 Inputs'!AR12 -> 0 | Y12: ='Stage 1 Inputs'!AS12 -> 0 | Z12: ='Stage 1 Inputs'!AT12 -> 0 | AA12: ='Stage 1 Inputs'!AU12 -> 1 | AB12: ='Stage 1 Inputs'!AV12 -> 0 | ... AE12: ='Stage 1 Inputs'!AY12 -> No special note
A13: ='Stage 1 Inputs'!A13 -> 2004Q4 | B13: ='Stage 1 Inputs'!B13 -> Dec 2004 | C13: ='Stage 1 Inputs'!G13 -> 38871000000 | D13: ='Stage 1 Inputs'!H13 -> 4114300 | E13: ='Stage 1 Inputs'!I13 -> 9447.7797 | F13: ='Stage 1 Inputs'!E13 -> 879 | G13: ='Stage 1 Inputs'!F13 -> 1.7758817 | H13: ='Stage 1 Inputs'!K13 -> 16778.139 | I13: ='Stage 1 Inputs'!M13 -> 9.7278321 | J13: ='Stage 1 Inputs'!N13 -> 118.4 | K13: ='Stage 1 Inputs'!D13 -> 1.7299742 | L13: ='Stage 1 Inputs'!O13 -> 204.82894 | M13: ='Stage 1 Inputs'!P13 -> 5.3221752 | N13: ='Stage 1 Inputs'!T13 -> 1897.6679 | O13: ='Stage 1 Inputs'!U13 -> 7.8075749e+09 | P13: ='Stage 1 Inputs'!V13 -> 7.548381 | Q13: ='Stage 1 Inputs'!W13 -> 22.77836 | R13: ='Stage 1 Inputs'!X13 -> 3.7 | S13: ='Stage 1 Inputs'!Y13 -> 0.037 | T13: ='Stage 1 Inputs'!Z13 -> -3.2968374 | U13: ='Stage 1 Inputs'!AO13 -> 12 | V13: ='Stage 1 Inputs'!AP13 -> 2.4849066 | W13: ='Stage 1 Inputs'!AQ13 -> 0 | X13: ='Stage 1 Inputs'!AR13 -> 0 | Y13: ='Stage 1 Inputs'!AS13 -> 0 | Z13: ='Stage 1 Inputs'!AT13 -> 0 | AA13: ='Stage 1 Inputs'!AU13 -> 0 | AB13: ='Stage 1 Inputs'!AV13 -> 1 | ... AE13: ='Stage 1 Inputs'!AY13 -> No special note
... A98: ='Stage 1 Inputs'!A98 -> 2026Q1 | B98: ='Stage 1 Inputs'!B98 -> Mar 2026 | C98: ='Stage 1 Inputs'!G98 -> 0 | D98: ='Stage 1 Inputs'!H98 -> 0 | E98: ='Stage 1 Inputs'!I98 -> 0 | F98: ='Stage 1 Inputs'!E98 -> 0 | G98: ='Stage 1 Inputs'!F98 -> 0 | H98: ='Stage 1 Inputs'!K98 -> 0 | I98: ='Stage 1 Inputs'!M98 -> 0 | J98: ='Stage 1 Inputs'!N98 -> 269.8 | K98: ='Stage 1 Inputs'!D98 -> 1 | L98: ='Stage 1 Inputs'!O98 -> 269.8 | M98: ='Stage 1 Inputs'!P98 -> 5.5976809 | N98: ='Stage 1 Inputs'!T98 -> 0 | O98: ='Stage 1 Inputs'!U98 -> 0 | P98: ='Stage 1 Inputs'!V98 -> 0 | Q98: ='Stage 1 Inputs'!W98 -> 0 | R98: ='Stage 1 Inputs'!X98 -> 0 | S98: ='Stage 1 Inputs'!Y98 -> 0 | T98: ='Stage 1 Inputs'!Z98 -> 0 | U98: ='Stage 1 Inputs'!AO98 -> 97 | V98: ='Stage 1 Inputs'!AP98 -> 4.574711 | W98: ='Stage 1 Inputs'!AQ98 -> 1 | X98: ='Stage 1 Inputs'!AR98 -> 0 | Y98: ='Stage 1 Inputs'!AS98 -> 1 | Z98: ='Stage 1 Inputs'!AT98 -> 0 | AA98: ='Stage 1 Inputs'!AU98 -> 0 | AB98: ='Stage 1 Inputs'!AV98 -> 0 | ... AE98: ='Stage 1 Inputs'!AY98 -> CPI and fuel values are official; GDP, population, labour, VKT and RUC volume/revenue are not yet released and remain zero.

Sheet Light RUC Inputs
A1: Quarter | B1: Period | C1: Nominal GDP (SA, NZD) | D1: GDP deflator (seasonally adjusted) | E1: GDP rebasing factor | F1: Real GDP (SA, NZD) | G1: Log real GDP | H1: Diesel price (nominal, cents/litre) | I1: CPI rebasing factor | J1: Diesel price (real, cents/litre) | K1: Log real diesel price | L1: Light RUC revenue (NZD) | M1: Light RUC net km | N1: Light RUC price (nominal, NZD/1,000 km) | O1: Light RUC price (real, NZD/1,000 km) | P1: Log real light RUC price | Q1: Lagged light RUC price (real, NZD/1,000 km) | R1: Log lagged light RUC price | S1: Q2 dummy | T1: Q3 dummy | U1: Q4 dummy | V1: Post-2020 dummy | W1: Data status | X1: Notes
A2: ='Stage 1 Inputs'!A2 -> 2002Q1 | B2: ='Stage 1 Inputs'!B2 -> Mar 2002 | C2: ='Stage 1 Inputs'!G2 -> 32976000000 | D2: ='Stage 1 Inputs'!E2 -> 835 | E2: ='Stage 1 Inputs'!F2 -> 1.8694611 | F2: ='Stage 1 Inputs'!J2 -> 6.1647349e+10 | G2: ='Stage 1 Inputs'!L2 -> 24.844696 | H2: ='Stage 1 Inputs'!Q2 -> 61.452198 | I2: ='Stage 1 Inputs'!D2 -> 1.8418157 | J2: ='Stage 1 Inputs'!R2 -> 113.18362 | K2: ='Stage 1 Inputs'!S2 -> 4.7290115 | L2: ='Stage 1 Inputs'!AA2 -> 0 | M2: ='Stage 1 Inputs'!AB2 -> 0 | N2: ='Stage 1 Inputs'!AC2 -> 0 | O2: ='Stage 1 Inputs'!AD2 -> 0 | P2: ='Stage 1 Inputs'!AE2 -> 0 | Q2: ='Stage 1 Inputs'!AF2 -> 0 | R2: ='Stage 1 Inputs'!AG2 -> 0 | S2: ='Stage 1 Inputs'!AT2 -> 0 | T2: ='Stage 1 Inputs'!AU2 -> 0 | U2: ='Stage 1 Inputs'!AV2 -> 0 | V2: ='Stage 1 Inputs'!AS2 -> 0 | W2: ='Stage 1 Inputs'!AX2 -> Historical official/source data | X2: ='Stage 1 Inputs'!AY2 -> No special note
A3: ='Stage 1 Inputs'!A3 -> 2002Q2 | B3: ='Stage 1 Inputs'!B3 -> Jun 2002 | C3: ='Stage 1 Inputs'!G3 -> 32897000000 | D3: ='Stage 1 Inputs'!E3 -> 825 | E3: ='Stage 1 Inputs'!F3 -> 1.8921212 | F3: ='Stage 1 Inputs'!J3 -> 6.2245112e+10 | G3: ='Stage 1 Inputs'!L3 -> 24.854346 | H3: ='Stage 1 Inputs'!Q3 -> 65.6 | I3: ='Stage 1 Inputs'!D3 -> 1.8242507 | J3: ='Stage 1 Inputs'!R3 -> 119.67084 | K3: ='Stage 1 Inputs'!S3 -> 4.784745 | L3: ='Stage 1 Inputs'!AA3 -> 0 | M3: ='Stage 1 Inputs'!AB3 -> 0 | N3: ='Stage 1 Inputs'!AC3 -> 0 | O3: ='Stage 1 Inputs'!AD3 -> 0 | P3: ='Stage 1 Inputs'!AE3 -> 0 | Q3: ='Stage 1 Inputs'!AF3 -> 0 | R3: ='Stage 1 Inputs'!AG3 -> 0 | S3: ='Stage 1 Inputs'!AT3 -> 1 | T3: ='Stage 1 Inputs'!AU3 -> 0 | U3: ='Stage 1 Inputs'!AV3 -> 0 | V3: ='Stage 1 Inputs'!AS3 -> 0 | W3: ='Stage 1 Inputs'!AX3 -> Historical official/source data | X3: ='Stage 1 Inputs'!AY3 -> No special note
A4: ='Stage 1 Inputs'!A4 -> 2002Q3 | B4: ='Stage 1 Inputs'!B4 -> Sep 2002 | C4: ='Stage 1 Inputs'!G4 -> 33866000000 | D4: ='Stage 1 Inputs'!E4 -> 832 | E4: ='Stage 1 Inputs'!F4 -> 1.8762019 | F4: ='Stage 1 Inputs'!J4 -> 6.3539454e+10 | G4: ='Stage 1 Inputs'!L4 -> 24.874927 | H4: ='Stage 1 Inputs'!Q4 -> 64.5 | I4: ='Stage 1 Inputs'!D4 -> 1.8143631 | J4: ='Stage 1 Inputs'!R4 -> 117.02642 | K4: ='Stage 1 Inputs'!S4 -> 4.7623997 | L4: ='Stage 1 Inputs'!AA4 -> 0 | M4: ='Stage 1 Inputs'!AB4 -> 0 | N4: ='Stage 1 Inputs'!AC4 -> 0 | O4: ='Stage 1 Inputs'!AD4 -> 0 | P4: ='Stage 1 Inputs'!AE4 -> 0 | Q4: ='Stage 1 Inputs'!AF4 -> 0 | R4: ='Stage 1 Inputs'!AG4 -> 0 | S4: ='Stage 1 Inputs'!AT4 -> 0 | T4: ='Stage 1 Inputs'!AU4 -> 1 | U4: ='Stage 1 Inputs'!AV4 -> 0 | V4: ='Stage 1 Inputs'!AS4 -> 0 | W4: ='Stage 1 Inputs'!AX4 -> Historical official/source data | X4: ='Stage 1 Inputs'!AY4 -> No special note
A5: ='Stage 1 Inputs'!A5 -> 2002Q4 | B5: ='Stage 1 Inputs'!B5 -> Dec 2002 | C5: ='Stage 1 Inputs'!G5 -> 33950000000 | D5: ='Stage 1 Inputs'!E5 -> 820 | E5: ='Stage 1 Inputs'!F5 -> 1.9036585 | F5: ='Stage 1 Inputs'!J5 -> 6.4629207e+10 | G5: ='Stage 1 Inputs'!L5 -> 24.891932 | H5: ='Stage 1 Inputs'!Q5 -> 65.4 | I5: ='Stage 1 Inputs'!D5 -> 1.8045822 | J5: ='Stage 1 Inputs'!R5 -> 118.01968 | K5: ='Stage 1 Inputs'!S5 -> 4.7708514 | L5: ='Stage 1 Inputs'!AA5 -> 0 | M5: ='Stage 1 Inputs'!AB5 -> 0 | N5: ='Stage 1 Inputs'!AC5 -> 0 | O5: ='Stage 1 Inputs'!AD5 -> 0 | P5: ='Stage 1 Inputs'!AE5 -> 0 | Q5: ='Stage 1 Inputs'!AF5 -> 0 | R5: ='Stage 1 Inputs'!AG5 -> 0 | S5: ='Stage 1 Inputs'!AT5 -> 0 | T5: ='Stage 1 Inputs'!AU5 -> 0 | U5: ='Stage 1 Inputs'!AV5 -> 1 | V5: ='Stage 1 Inputs'!AS5 -> 0 | W5: ='Stage 1 Inputs'!AX5 -> Historical official/source data | X5: ='Stage 1 Inputs'!AY5 -> No special note
A6: ='Stage 1 Inputs'!A6 -> 2003Q1 | B6: ='Stage 1 Inputs'!B6 -> Mar 2003 | C6: ='Stage 1 Inputs'!G6 -> 34462000000 | D6: ='Stage 1 Inputs'!E6 -> 828 | E6: ='Stage 1 Inputs'!F6 -> 1.8852657 | F6: ='Stage 1 Inputs'!J6 -> 6.4970027e+10 | G6: ='Stage 1 Inputs'!L6 -> 24.897192 | H6: ='Stage 1 Inputs'!Q6 -> 70.8 | I6: ='Stage 1 Inputs'!D6 -> 1.7973154 | J6: ='Stage 1 Inputs'!R6 -> 127.24993 | K6: ='Stage 1 Inputs'!S6 -> 4.8461531 | L6: ='Stage 1 Inputs'!AA6 -> 0 | M6: ='Stage 1 Inputs'!AB6 -> 0 | N6: ='Stage 1 Inputs'!AC6 -> 0 | O6: ='Stage 1 Inputs'!AD6 -> 0 | P6: ='Stage 1 Inputs'!AE6 -> 0 | Q6: ='Stage 1 Inputs'!AF6 -> 0 | R6: ='Stage 1 Inputs'!AG6 -> 0 | S6: ='Stage 1 Inputs'!AT6 -> 0 | T6: ='Stage 1 Inputs'!AU6 -> 0 | U6: ='Stage 1 Inputs'!AV6 -> 0 | V6: ='Stage 1 Inputs'!AS6 -> 0 | W6: ='Stage 1 Inputs'!AX6 -> Historical official/source data | X6: ='Stage 1 Inputs'!AY6 -> No special note
A7: ='Stage 1 Inputs'!A7 -> 2003Q2 | B7: ='Stage 1 Inputs'!B7 -> Jun 2003 | C7: ='Stage 1 Inputs'!G7 -> 34938000000 | D7: ='Stage 1 Inputs'!E7 -> 836 | E7: ='Stage 1 Inputs'!F7 -> 1.8672249 | F7: ='Stage 1 Inputs'!J7 -> 6.5237103e+10 | G7: ='Stage 1 Inputs'!L7 -> 24.901294 | H7: ='Stage 1 Inputs'!Q7 -> 59.3 | I7: ='Stage 1 Inputs'!D7 -> 1.7973154 | J7: ='Stage 1 Inputs'!R7 -> 106.58081 | K7: ='Stage 1 Inputs'!S7 -> 4.6689034 | L7: ='Stage 1 Inputs'!AA7 -> 0 | M7: ='Stage 1 Inputs'!AB7 -> 0 | N7: ='Stage 1 Inputs'!AC7 -> 0 | O7: ='Stage 1 Inputs'!AD7 -> 0 | P7: ='Stage 1 Inputs'!AE7 -> 0 | Q7: ='Stage 1 Inputs'!AF7 -> 0 | R7: ='Stage 1 Inputs'!AG7 -> 0 | S7: ='Stage 1 Inputs'!AT7 -> 1 | T7: ='Stage 1 Inputs'!AU7 -> 0 | U7: ='Stage 1 Inputs'!AV7 -> 0 | V7: ='Stage 1 Inputs'!AS7 -> 0 | W7: ='Stage 1 Inputs'!AX7 -> Historical official/source data | X7: ='Stage 1 Inputs'!AY7 -> No special note
A8: ='Stage 1 Inputs'!A8 -> 2003Q3 | B8: ='Stage 1 Inputs'!B8 -> Sep 2003 | C8: ='Stage 1 Inputs'!G8 -> 35703000000 | D8: ='Stage 1 Inputs'!E8 -> 841 | E8: ='Stage 1 Inputs'!F8 -> 1.8561237 | F8: ='Stage 1 Inputs'!J8 -> 6.6269183e+10 | G8: ='Stage 1 Inputs'!L8 -> 24.916991 | H8: ='Stage 1 Inputs'!Q8 -> 60.2 | I8: ='Stage 1 Inputs'!D8 -> 1.790107 | J8: ='Stage 1 Inputs'!R8 -> 107.76444 | K8: ='Stage 1 Inputs'!S8 -> 4.6799477 | L8: ='Stage 1 Inputs'!AA8 -> 0 | M8: ='Stage 1 Inputs'!AB8 -> 0 | N8: ='Stage 1 Inputs'!AC8 -> 0 | O8: ='Stage 1 Inputs'!AD8 -> 0 | P8: ='Stage 1 Inputs'!AE8 -> 0 | Q8: ='Stage 1 Inputs'!AF8 -> 0 | R8: ='Stage 1 Inputs'!AG8 -> 0 | S8: ='Stage 1 Inputs'!AT8 -> 0 | T8: ='Stage 1 Inputs'!AU8 -> 1 | U8: ='Stage 1 Inputs'!AV8 -> 0 | V8: ='Stage 1 Inputs'!AS8 -> 0 | W8: ='Stage 1 Inputs'!AX8 -> Historical official/source data | X8: ='Stage 1 Inputs'!AY8 -> No special note
A9: ='Stage 1 Inputs'!A9 -> 2003Q4 | B9: ='Stage 1 Inputs'!B9 -> Dec 2003 | C9: ='Stage 1 Inputs'!G9 -> 36381000000 | D9: ='Stage 1 Inputs'!E9 -> 847 | E9: ='Stage 1 Inputs'!F9 -> 1.8429752 | F9: ='Stage 1 Inputs'!J9 -> 6.7049281e+10 | G9: ='Stage 1 Inputs'!L9 -> 24.928694 | H9: ='Stage 1 Inputs'!Q9 -> 58.2 | I9: ='Stage 1 Inputs'!D9 -> 1.7758621 | J9: ='Stage 1 Inputs'!R9 -> 103.35517 | K9: ='Stage 1 Inputs'!S9 -> 4.6381713 | L9: ='Stage 1 Inputs'!AA9 -> 0 | M9: ='Stage 1 Inputs'!AB9 -> 0 | N9: ='Stage 1 Inputs'!AC9 -> 0 | O9: ='Stage 1 Inputs'!AD9 -> 0 | P9: ='Stage 1 Inputs'!AE9 -> 0 | Q9: ='Stage 1 Inputs'!AF9 -> 0 | R9: ='Stage 1 Inputs'!AG9 -> 0 | S9: ='Stage 1 Inputs'!AT9 -> 0 | T9: ='Stage 1 Inputs'!AU9 -> 0 | U9: ='Stage 1 Inputs'!AV9 -> 1 | V9: ='Stage 1 Inputs'!AS9 -> 0 | W9: ='Stage 1 Inputs'!AX9 -> Historical official/source data | X9: ='Stage 1 Inputs'!AY9 -> No special note
A10: ='Stage 1 Inputs'!A10 -> 2004Q1 | B10: ='Stage 1 Inputs'!B10 -> Mar 2004 | C10: ='Stage 1 Inputs'!G10 -> 37466000000 | D10: ='Stage 1 Inputs'!E10 -> 850 | E10: ='Stage 1 Inputs'!F10 -> 1.8364706 | F10: ='Stage 1 Inputs'!J10 -> 6.8805207e+10 | G10: ='Stage 1 Inputs'!L10 -> 24.954545 | H10: ='Stage 1 Inputs'!Q10 -> 63.7 | I10: ='Stage 1 Inputs'!D10 -> 1.7688243 | J10: ='Stage 1 Inputs'!R10 -> 112.67411 | K10: ='Stage 1 Inputs'!S10 -> 4.7244997 | L10: ='Stage 1 Inputs'!AA10 -> 0 | M10: ='Stage 1 Inputs'!AB10 -> 0 | N10: ='Stage 1 Inputs'!AC10 -> 0 | O10: ='Stage 1 Inputs'!AD10 -> 0 | P10: ='Stage 1 Inputs'!AE10 -> 0 | Q10: ='Stage 1 Inputs'!AF10 -> 0 | R10: ='Stage 1 Inputs'!AG10 -> 0 | S10: ='Stage 1 Inputs'!AT10 -> 0 | T10: ='Stage 1 Inputs'!AU10 -> 0 | U10: ='Stage 1 Inputs'!AV10 -> 0 | V10: ='Stage 1 Inputs'!AS10 -> 0 | W10: ='Stage 1 Inputs'!AX10 -> Historical official/source data | X10: ='Stage 1 Inputs'!AY10 -> No special note
A11: ='Stage 1 Inputs'!A11 -> 2004Q2 | B11: ='Stage 1 Inputs'!B11 -> Jun 2004 | C11: ='Stage 1 Inputs'!G11 -> 38019000000 | D11: ='Stage 1 Inputs'!E11 -> 862 | E11: ='Stage 1 Inputs'!F11 -> 1.8109049 | F11: ='Stage 1 Inputs'!J11 -> 6.8848792e+10 | G11: ='Stage 1 Inputs'!L11 -> 24.955179 | H11: ='Stage 1 Inputs'!Q11 -> 71.6 | I11: ='Stage 1 Inputs'!D11 -> 1.7549148 | J11: ='Stage 1 Inputs'!R11 -> 125.6519 | K11: ='Stage 1 Inputs'!S11 -> 4.8335154 | L11: ='Stage 1 Inputs'!AA11 -> 0 | M11: ='Stage 1 Inputs'!AB11 -> 0 | N11: ='Stage 1 Inputs'!AC11 -> 0 | O11: ='Stage 1 Inputs'!AD11 -> 0 | P11: ='Stage 1 Inputs'!AE11 -> 0 | Q11: ='Stage 1 Inputs'!AF11 -> 0 | R11: ='Stage 1 Inputs'!AG11 -> 0 | S11: ='Stage 1 Inputs'!AT11 -> 1 | T11: ='Stage 1 Inputs'!AU11 -> 0 | U11: ='Stage 1 Inputs'!AV11 -> 0 | V11: ='Stage 1 Inputs'!AS11 -> 0 | W11: ='Stage 1 Inputs'!AX11 -> Historical official/source data | X11: ='Stage 1 Inputs'!AY11 -> No special note
A12: ='Stage 1 Inputs'!A12 -> 2004Q3 | B12: ='Stage 1 Inputs'!B12 -> Sep 2004 | C12: ='Stage 1 Inputs'!G12 -> 38645000000 | D12: ='Stage 1 Inputs'!E12 -> 875 | E12: ='Stage 1 Inputs'!F12 -> 1.784 | F12: ='Stage 1 Inputs'!J12 -> 68942680000 | G12: ='Stage 1 Inputs'!L12 -> 24.956541 | H12: ='Stage 1 Inputs'!Q12 -> 76.4 | I12: ='Stage 1 Inputs'!D12 -> 1.7457627 | J12: ='Stage 1 Inputs'!R12 -> 133.37627 | K12: ='Stage 1 Inputs'!S12 -> 4.8931742 | L12: ='Stage 1 Inputs'!AA12 -> 0 | M12: ='Stage 1 Inputs'!AB12 -> 0 | N12: ='Stage 1 Inputs'!AC12 -> 0 | O12: ='Stage 1 Inputs'!AD12 -> 0 | P12: ='Stage 1 Inputs'!AE12 -> 0 | Q12: ='Stage 1 Inputs'!AF12 -> 0 | R12: ='Stage 1 Inputs'!AG12 -> 0 | S12: ='Stage 1 Inputs'!AT12 -> 0 | T12: ='Stage 1 Inputs'!AU12 -> 1 | U12: ='Stage 1 Inputs'!AV12 -> 0 | V12: ='Stage 1 Inputs'!AS12 -> 0 | W12: ='Stage 1 Inputs'!AX12 -> Historical official/source data | X12: ='Stage 1 Inputs'!AY12 -> No special note
A13: ='Stage 1 Inputs'!A13 -> 2004Q4 | B13: ='Stage 1 Inputs'!B13 -> Dec 2004 | C13: ='Stage 1 Inputs'!G13 -> 38871000000 | D13: ='Stage 1 Inputs'!E13 -> 879 | E13: ='Stage 1 Inputs'!F13 -> 1.7758817 | F13: ='Stage 1 Inputs'!J13 -> 6.9030297e+10 | G13: ='Stage 1 Inputs'!L13 -> 24.957811 | H13: ='Stage 1 Inputs'!Q13 -> 80.2 | I13: ='Stage 1 Inputs'!D13 -> 1.7299742 | J13: ='Stage 1 Inputs'!R13 -> 138.74393 | K13: ='Stage 1 Inputs'!S13 -> 4.93263 | L13: ='Stage 1 Inputs'!AA13 -> 0 | M13: ='Stage 1 Inputs'!AB13 -> 0 | N13: ='Stage 1 Inputs'!AC13 -> 0 | O13: ='Stage 1 Inputs'!AD13 -> 0 | P13: ='Stage 1 Inputs'!AE13 -> 0 | Q13: ='Stage 1 Inputs'!AF13 -> 0 | R13: ='Stage 1 Inputs'!AG13 -> 0 | S13: ='Stage 1 Inputs'!AT13 -> 0 | T13: ='Stage 1 Inputs'!AU13 -> 0 | U13: ='Stage 1 Inputs'!AV13 -> 1 | V13: ='Stage 1 Inputs'!AS13 -> 0 | W13: ='Stage 1 Inputs'!AX13 -> Historical official/source data | X13: ='Stage 1 Inputs'!AY13 -> No special note
... A98: ='Stage 1 Inputs'!A98 -> 2026Q1 | B98: ='Stage 1 Inputs'!B98 -> Mar 2026 | C98: ='Stage 1 Inputs'!G98 -> 0 | D98: ='Stage 1 Inputs'!E98 -> 0 | E98: ='Stage 1 Inputs'!F98 -> 0 | F98: ='Stage 1 Inputs'!J98 -> 0 | G98: ='Stage 1 Inputs'!L98 -> 0 | H98: ='Stage 1 Inputs'!Q98 -> 214.6 | I98: ='Stage 1 Inputs'!D98 -> 1 | J98: ='Stage 1 Inputs'!R98 -> 214.6 | K98: ='Stage 1 Inputs'!S98 -> 5.3687758 | L98: ='Stage 1 Inputs'!AA98 -> 0 | M98: ='Stage 1 Inputs'!AB98 -> 0 | N98: ='Stage 1 Inputs'!AC98 -> 0 | O98: ='Stage 1 Inputs'!AD98 -> 0 | P98: ='Stage 1 Inputs'!AE98 -> 0 | Q98: ='Stage 1 Inputs'!AF98 -> 78.619585 | R98: ='Stage 1 Inputs'!AG98 -> 4.3646208 | S98: ='Stage 1 Inputs'!AT98 -> 0 | T98: ='Stage 1 Inputs'!AU98 -> 0 | U98: ='Stage 1 Inputs'!AV98 -> 0 | V98: ='Stage 1 Inputs'!AS98 -> 1 | W98: ='Stage 1 Inputs'!AX98 -> Partial official CPI and fuel update | X98: ='Stage 1 Inputs'!AY98 -> CPI and fuel values are official; GDP, population, labour, VKT and RUC volume/revenue are not yet released and remain zero.

Sheet Heavy RUC Inputs
A1: Quarter | B1: Period | C1: Nominal GDP (SA, NZD) | D1: GDP deflator (seasonally adjusted) | E1: GDP rebasing factor | F1: Real GDP (SA, NZD) | G1: Log real GDP | H1: Heavy RUC revenue (NZD) | I1: Heavy RUC net km | J1: Heavy RUC price (nominal, NZD/1,000 km) | K1: Heavy RUC price (real, NZD/1,000 km) | L1: Log real heavy RUC price | M1: Lead heavy RUC price (real, NZD/1,000 km) | N1: Log lead heavy RUC price | O1: Q2 dummy | P1: Q3 dummy | Q1: Q4 dummy | R1: Data status | S1: Notes
A2: ='Stage 1 Inputs'!A2 -> 2002Q1 | B2: ='Stage 1 Inputs'!B2 -> Mar 2002 | C2: ='Stage 1 Inputs'!G2 -> 32976000000 | D2: ='Stage 1 Inputs'!E2 -> 835 | E2: ='Stage 1 Inputs'!F2 -> 1.8694611 | F2: ='Stage 1 Inputs'!J2 -> 6.1647349e+10 | G2: ='Stage 1 Inputs'!L2 -> 24.844696 | H2: ='Stage 1 Inputs'!AH2 -> 0 | I2: ='Stage 1 Inputs'!AI2 -> 0 | J2: ='Stage 1 Inputs'!AJ2 -> 0 | K2: ='Stage 1 Inputs'!AK2 -> 0 | L2: ='Stage 1 Inputs'!AL2 -> 0 | M2: ='Stage 1 Inputs'!AM2 -> 0 | N2: ='Stage 1 Inputs'!AN2 -> 0 | O2: ='Stage 1 Inputs'!AT2 -> 0 | P2: ='Stage 1 Inputs'!AU2 -> 0 | Q2: ='Stage 1 Inputs'!AV2 -> 0 | R2: ='Stage 1 Inputs'!AX2 -> Historical official/source data | S2: ='Stage 1 Inputs'!AY2 -> No special note
A3: ='Stage 1 Inputs'!A3 -> 2002Q2 | B3: ='Stage 1 Inputs'!B3 -> Jun 2002 | C3: ='Stage 1 Inputs'!G3 -> 32897000000 | D3: ='Stage 1 Inputs'!E3 -> 825 | E3: ='Stage 1 Inputs'!F3 -> 1.8921212 | F3: ='Stage 1 Inputs'!J3 -> 6.2245112e+10 | G3: ='Stage 1 Inputs'!L3 -> 24.854346 | H3: ='Stage 1 Inputs'!AH3 -> 0 | I3: ='Stage 1 Inputs'!AI3 -> 0 | J3: ='Stage 1 Inputs'!AJ3 -> 0 | K3: ='Stage 1 Inputs'!AK3 -> 0 | L3: ='Stage 1 Inputs'!AL3 -> 0 | M3: ='Stage 1 Inputs'!AM3 -> 0 | N3: ='Stage 1 Inputs'!AN3 -> 0 | O3: ='Stage 1 Inputs'!AT3 -> 1 | P3: ='Stage 1 Inputs'!AU3 -> 0 | Q3: ='Stage 1 Inputs'!AV3 -> 0 | R3: ='Stage 1 Inputs'!AX3 -> Historical official/source data | S3: ='Stage 1 Inputs'!AY3 -> No special note
A4: ='Stage 1 Inputs'!A4 -> 2002Q3 | B4: ='Stage 1 Inputs'!B4 -> Sep 2002 | C4: ='Stage 1 Inputs'!G4 -> 33866000000 | D4: ='Stage 1 Inputs'!E4 -> 832 | E4: ='Stage 1 Inputs'!F4 -> 1.8762019 | F4: ='Stage 1 Inputs'!J4 -> 6.3539454e+10 | G4: ='Stage 1 Inputs'!L4 -> 24.874927 | H4: ='Stage 1 Inputs'!AH4 -> 0 | I4: ='Stage 1 Inputs'!AI4 -> 0 | J4: ='Stage 1 Inputs'!AJ4 -> 0 | K4: ='Stage 1 Inputs'!AK4 -> 0 | L4: ='Stage 1 Inputs'!AL4 -> 0 | M4: ='Stage 1 Inputs'!AM4 -> 0 | N4: ='Stage 1 Inputs'!AN4 -> 0 | O4: ='Stage 1 Inputs'!AT4 -> 0 | P4: ='Stage 1 Inputs'!AU4 -> 1 | Q4: ='Stage 1 Inputs'!AV4 -> 0 | R4: ='Stage 1 Inputs'!AX4 -> Historical official/source data | S4: ='Stage 1 Inputs'!AY4 -> No special note
A5: ='Stage 1 Inputs'!A5 -> 2002Q4 | B5: ='Stage 1 Inputs'!B5 -> Dec 2002 | C5: ='Stage 1 Inputs'!G5 -> 33950000000 | D5: ='Stage 1 Inputs'!E5 -> 820 | E5: ='Stage 1 Inputs'!F5 -> 1.9036585 | F5: ='Stage 1 Inputs'!J5 -> 6.4629207e+10 | G5: ='Stage 1 Inputs'!L5 -> 24.891932 | H5: ='Stage 1 Inputs'!AH5 -> 0 | I5: ='Stage 1 Inputs'!AI5 -> 0 | J5: ='Stage 1 Inputs'!AJ5 -> 0 | K5: ='Stage 1 Inputs'!AK5 -> 0 | L5: ='Stage 1 Inputs'!AL5 -> 0 | M5: ='Stage 1 Inputs'!AM5 -> 0 | N5: ='Stage 1 Inputs'!AN5 -> 0 | O5: ='Stage 1 Inputs'!AT5 -> 0 | P5: ='Stage 1 Inputs'!AU5 -> 0 | Q5: ='Stage 1 Inputs'!AV5 -> 1 | R5: ='Stage 1 Inputs'!AX5 -> Historical official/source data | S5: ='Stage 1 Inputs'!AY5 -> No special note
A6: ='Stage 1 Inputs'!A6 -> 2003Q1 | B6: ='Stage 1 Inputs'!B6 -> Mar 2003 | C6: ='Stage 1 Inputs'!G6 -> 34462000000 | D6: ='Stage 1 Inputs'!E6 -> 828 | E6: ='Stage 1 Inputs'!F6 -> 1.8852657 | F6: ='Stage 1 Inputs'!J6 -> 6.4970027e+10 | G6: ='Stage 1 Inputs'!L6 -> 24.897192 | H6: ='Stage 1 Inputs'!AH6 -> 0 | I6: ='Stage 1 Inputs'!AI6 -> 0 | J6: ='Stage 1 Inputs'!AJ6 -> 0 | K6: ='Stage 1 Inputs'!AK6 -> 0 | L6: ='Stage 1 Inputs'!AL6 -> 0 | M6: ='Stage 1 Inputs'!AM6 -> 0 | N6: ='Stage 1 Inputs'!AN6 -> 0 | O6: ='Stage 1 Inputs'!AT6 -> 0 | P6: ='Stage 1 Inputs'!AU6 -> 0 | Q6: ='Stage 1 Inputs'!AV6 -> 0 | R6: ='Stage 1 Inputs'!AX6 -> Historical official/source data | S6: ='Stage 1 Inputs'!AY6 -> No special note
A7: ='Stage 1 Inputs'!A7 -> 2003Q2 | B7: ='Stage 1 Inputs'!B7 -> Jun 2003 | C7: ='Stage 1 Inputs'!G7 -> 34938000000 | D7: ='Stage 1 Inputs'!E7 -> 836 | E7: ='Stage 1 Inputs'!F7 -> 1.8672249 | F7: ='Stage 1 Inputs'!J7 -> 6.5237103e+10 | G7: ='Stage 1 Inputs'!L7 -> 24.901294 | H7: ='Stage 1 Inputs'!AH7 -> 0 | I7: ='Stage 1 Inputs'!AI7 -> 0 | J7: ='Stage 1 Inputs'!AJ7 -> 0 | K7: ='Stage 1 Inputs'!AK7 -> 0 | L7: ='Stage 1 Inputs'!AL7 -> 0 | M7: ='Stage 1 Inputs'!AM7 -> 0 | N7: ='Stage 1 Inputs'!AN7 -> 0 | O7: ='Stage 1 Inputs'!AT7 -> 1 | P7: ='Stage 1 Inputs'!AU7 -> 0 | Q7: ='Stage 1 Inputs'!AV7 -> 0 | R7: ='Stage 1 Inputs'!AX7 -> Historical official/source data | S7: ='Stage 1 Inputs'!AY7 -> No special note
A8: ='Stage 1 Inputs'!A8 -> 2003Q3 | B8: ='Stage 1 Inputs'!B8 -> Sep 2003 | C8: ='Stage 1 Inputs'!G8 -> 35703000000 | D8: ='Stage 1 Inputs'!E8 -> 841 | E8: ='Stage 1 Inputs'!F8 -> 1.8561237 | F8: ='Stage 1 Inputs'!J8 -> 6.6269183e+10 | G8: ='Stage 1 Inputs'!L8 -> 24.916991 | H8: ='Stage 1 Inputs'!AH8 -> 0 | I8: ='Stage 1 Inputs'!AI8 -> 0 | J8: ='Stage 1 Inputs'!AJ8 -> 0 | K8: ='Stage 1 Inputs'!AK8 -> 0 | L8: ='Stage 1 Inputs'!AL8 -> 0 | M8: ='Stage 1 Inputs'!AM8 -> 0 | N8: ='Stage 1 Inputs'!AN8 -> 0 | O8: ='Stage 1 Inputs'!AT8 -> 0 | P8: ='Stage 1 Inputs'!AU8 -> 1 | Q8: ='Stage 1 Inputs'!AV8 -> 0 | R8: ='Stage 1 Inputs'!AX8 -> Historical official/source data | S8: ='Stage 1 Inputs'!AY8 -> No special note
A9: ='Stage 1 Inputs'!A9 -> 2003Q4 | B9: ='Stage 1 Inputs'!B9 -> Dec 2003 | C9: ='Stage 1 Inputs'!G9 -> 36381000000 | D9: ='Stage 1 Inputs'!E9 -> 847 | E9: ='Stage 1 Inputs'!F9 -> 1.8429752 | F9: ='Stage 1 Inputs'!J9 -> 6.7049281e+10 | G9: ='Stage 1 Inputs'!L9 -> 24.928694 | H9: ='Stage 1 Inputs'!AH9 -> 0 | I9: ='Stage 1 Inputs'!AI9 -> 0 | J9: ='Stage 1 Inputs'!AJ9 -> 0 | K9: ='Stage 1 Inputs'!AK9 -> 0 | L9: ='Stage 1 Inputs'!AL9 -> 0 | M9: ='Stage 1 Inputs'!AM9 -> 0 | N9: ='Stage 1 Inputs'!AN9 -> 0 | O9: ='Stage 1 Inputs'!AT9 -> 0 | P9: ='Stage 1 Inputs'!AU9 -> 0 | Q9: ='Stage 1 Inputs'!AV9 -> 1 | R9: ='Stage 1 Inputs'!AX9 -> Historical official/source data | S9: ='Stage 1 Inputs'!AY9 -> No special note
A10: ='Stage 1 Inputs'!A10 -> 2004Q1 | B10: ='Stage 1 Inputs'!B10 -> Mar 2004 | C10: ='Stage 1 Inputs'!G10 -> 37466000000 | D10: ='Stage 1 Inputs'!E10 -> 850 | E10: ='Stage 1 Inputs'!F10 -> 1.8364706 | F10: ='Stage 1 Inputs'!J10 -> 6.8805207e+10 | G10: ='Stage 1 Inputs'!L10 -> 24.954545 | H10: ='Stage 1 Inputs'!AH10 -> 0 | I10: ='Stage 1 Inputs'!AI10 -> 0 | J10: ='Stage 1 Inputs'!AJ10 -> 0 | K10: ='Stage 1 Inputs'!AK10 -> 0 | L10: ='Stage 1 Inputs'!AL10 -> 0 | M10: ='Stage 1 Inputs'!AM10 -> 0 | N10: ='Stage 1 Inputs'!AN10 -> 0 | O10: ='Stage 1 Inputs'!AT10 -> 0 | P10: ='Stage 1 Inputs'!AU10 -> 0 | Q10: ='Stage 1 Inputs'!AV10 -> 0 | R10: ='Stage 1 Inputs'!AX10 -> Historical official/source data | S10: ='Stage 1 Inputs'!AY10 -> No special note
